Workbook

Sheet 18
B1: 45795 | E1: ME MAYO
E2: 207588
B3: DESPACHO DEL DÍA POR TIPO DE CEMENTO | H3: PLAN | I3: REAL | J3: %
D4: =D24 -> 4787.61 | F4: LUNES | G4: 45789 | H4: 6679 | I4: 6034.43 | J4: =+I4/H4 -> 0.90349304
B5: CEM. FRONTERA GU X 42.5 KG | C5: 760 | D5: 32.4 | F5: MARTES | G5: 45790 | H5: 8467 | I5: 8258.22 | J5: =+I5/H5 -> 0.97534192
B6: CEMENTO FRONTERA IP x 42.5 KG | C6: 13510 | D6: 577.034 | F6: MIÉRCOLES | G6: 45791 | H6: 7756 | I6: 7996.87 | J6: =+I6/H6 -> 1.031056
B7: CEMENTO HS+R X 42.5 KG RUMI | C7: 16090 | D7: 686.54 | F7: JUEVES | G7: 45792 | H7: 6272 | I7: 7600.04 | J7: =+I7/H7 -> 1.2117411
B8: CEMENTO PORTLAND TIPO I X 42.5 KG YURA | C8: 1490 | D8: 63.54 | F8: VIERNES | G8: 45793 | H8: 6051 | I8: 7593.12 | J8: =+I8/H8 -> 1.2548537
B9: CEMENTO YURA ANTISALITRE (MS) X 42.5 KG | C9: 15800 | D9: 674.722 | F9: SÁBADO | G9: 45794 | H9: 5851 | I9: 6283.62 | J9: =+I9/H9 -> 1.0739395
B10: CEMENTO YURA MAX (HS) X 42.5KG | C10: 23248 | D10: 991.952 | F10: DOMINGO | G10: 45795 | H10: 3600 | I10: 4787.61 | J10: =+I10/H10 -> 1.3298917
B11: CEMENTO YURA PRO (HE) 42.5KG | C11: 6857 | D11: 292.472 | H11: =+SUM(H4:H10) -> 44676 | I11: =+SUM(I4:I10) -> 48553.91 | J11: =+I11/H11 -> 1.0868007
B12: CEM.PORTL.IP(GRADO CORRIENTE)X25KG CHILE | C12: 5424 | D12: 137.302
B13: CEMENTO ANTISALITRE TIPO HS x 25KG YURA | C13: 1224 | D13: 30.818
B14: CEM. PORT. I BBx1.5TM INC.ENV YURA | C14: 41 | D14: 61.9
B15: CEMENTO YURA PRO (HE) BBx1.5TM INC.ENV | C15: 193 | D15: 291.84
B16: CEM ALT REST IN HE BB1.5TM YURA ENV CHIL | C16: 68 | D16: 102.83 | I16: =+E2*2% -> 4151.76 | K16: =+I16/1.5 -> 2767.84
B17: CEM.YURA ANTISALITRE MS BBx1.5TM INC.ENV
B18: CEMENTO YURA MAX BBx1.5TM INC.ENV | C18: 130 | D18: 195.29
B19: CEM. PORT. PUZ. IP BBx1.5TM INC.ENV YURA | C19: 107 | D19: 160.71 | E19: =+C19/D4 -> 0.022349356
B20: CEMENTO BLANCO BIGBAGx1.5TM EXP.BOLIVIA
B21: CEMENTO YURA PRO (HE) GRANEL EN BOMBONA | D21: 336.18
B22: CEMENTO YURA IP A GRANEL EN BOMBONA | D22: 152.08
B23: CEMENTO YURA MAX GRANEL BOMBONA
B24: DESPACHO T.M. DEL DIA | D24: =SUM(D5:D23) -> 4787.61
B25: ACUMULADO MES | D25: 117383.13 | E25: =+D25/E2 -> 0.56546203
D26: =+(E2/31)*18 -> 120534.97 | E26: =+D26/E2 -> 0.58064516
D27: =+D25-D26 -> -3151.8357 | E27: =+E25-E26 -> -0.015183131
B29: TEMPORALES
B30: TEMPORAL 1 | C30: 865
B31: TEMPORAL 2 | C31: 1618 | D31: CEMENTO BLANCO 25 Kg. | E31: 13159 | F31: 328.975
B32: MISTI | C32: 947 | D32: CEMENTO BLANCO BIGBAG x 1.5TM | E32: 208 | F32: 312
C33: =+SUM(C30:C32) -> 3430
B35: CARROS
B36: PLAYA | C36: LLAMADO | D36: PROCESO DE C | E36: TOTAL
B37: 2 | C37: 2 | D37: 10 | E37: =+SUM(B37:D37) -> 14
A39: H1 | E39: RENDIMIENTO
A40: H2 | B40: 4.33 | C40: 2374 | D40: 3600 | E40: =+C40/D40 -> 0.65944444
A41: H3 | B41: 7.52 | C41: 2898 | D41: 3600 | E41: =+C41/D41 -> 0.805
A42: H4 | B42: 10.34 | C42: 2273 | D42: 3900 | E42: =+C42/D42 -> 0.58282051
A43: H5 | B43: 8.57 | C43: 3029 | D43: 3900 | E43: =+C43/D43 -> 0.77666667
...

Sheet 19
B1: 45796 | E1: ME MAYO
E2: 207588
B3: DESPACHO DEL DÍA POR TIPO DE CEMENTO | H3: PLAN | I3: REAL | J3: %
D4: =D24 -> 6031.438 | F4: LUNES | G4: 45796 | H4: 6179 | I4: 6031.438 | J4: =+I4/H4 -> 0.97611879
B5: CEM. FRONTERA GU X 42.5 KG | C5: 3005 | D5: 128.16 | E5: =+D5/$D$4 -> 0.021248664 | F5: MARTES | G5: 45797 | H5: 8374 | J5: =+I5/H5 -> 0
B6: CEMENTO FRONTERA IP x 42.5 KG | C6: 15578 | D6: 665.804 | E6: =+D6/$D$4 -> 0.11038893 | F6: MIÉRCOLES | G6: 45798 | H6: 7620 | J6: =+I6/H6 -> 0
B7: CEMENTO HS+R X 42.5 KG RUMI | C7: 10908 | D7: 464.97 | E7: =+D7/$D$4 -> 0.077091068 | F7: JUEVES | G7: 45799 | H7: 7440 | J7: =+I7/H7 -> 0
B8: CEMENTO PORTLAND TIPO I X 42.5 KG YURA | C8: 2028 | D8: 86.529 | E8: =+D8/$D$4 -> 0.01434633 | F8: VIERNES | G8: 45800 | H8: 7740 | J8: =+I8/H8 -> 0
B9: CEMENTO YURA ANTISALITRE (MS) X 42.5 KG | C9: 21737 | D9: 928.714 | E9: =+D9/$D$4 -> 0.15397887 | F9: SÁBADO | G9: 45801 | H9: 6194 | J9: =+I9/H9 -> 0
B10: CEMENTO YURA MAX (HS) X 42.5KG | C10: 33794 | D10: 1441.177 | E10: =+D10/$D$4 -> 0.23894418 | F10: DOMINGO | G10: 45802 | H10: 4327 | J10: =+I10/H10 -> 0
B11: CEMENTO YURA PRO (HE) 42.5KG | C11: 7647 | D11: 326.274 | E11: =+D11/$D$4 -> 0.054095557 | H11: =+SUM(H4:H10) -> 47874 | I11: =+SUM(I4:I10) -> 6031.438 | J11: =+I11/H11 -> 0.12598567
B12: CEM YURA ESPECIAL (HS) X 42.5 KG | C12: 1620 | D12: 69.06 | E12: =+D12/$D$4 -> 0.011450006
B13: CEMENTO ANTISALITRE TIPO HS x 25KG YURA | E13: =+D13/$D$4 -> 0
B14: CEM. PORT. I BBx1.5TM INC.ENV YURA | C14: 22 | D14: 33.21 | E14: =+D14/$D$4 -> 0.0055061496
B15: CEMENTO YURA PRO (HE) BBx1.5TM INC.ENV | C15: 377 | D15: 569.08 | E15: =+D15/$D$4 -> 0.094352292
B16: CEM ALT REST IN HE BB1.5TM YURA ENV CHIL | C16: 226 | D16: 341.01 | E16: =+D16/$D$4 -> 0.056538756
B17: CEM.YURA ANTISALITRE MS BBx1.5TM INC.ENV | C17: 22 | D17: 33.06 | E17: =+D17/$D$4 -> 0.0054812799
B18: CEMENTO YURA MAX BBx1.5TM INC.ENV | C18: 265 | D18: 397.99 | E18: =+D18/$D$4 -> 0.065985922
B19: CEM. PORT. PUZ. IP BBx1.5TM INC.ENV YURA | C19: 21 | D19: 31.55 | E19: =+D19/$D$4 -> 0.005230925
B20: CEMENTO BLANCO BIGBAGx1.5TM EXP.BOLIVIA | D20: 30 | E20: =+D20/$D$4 -> 0.0049739382
B21: CEMENTO YURA PRO (HE) GRANEL EN BOMBONA | D21: 364.88 | E21: =+D21/$D$4 -> 0.060496353
B22: CEMENTO YURA IP A GRANEL EN BOMBONA | D22: 119.97 | E22: =+D22/$D$4 -> 0.019890779
B23: CEMENTO YURA MAX GRANEL BOMBONA | E23: =+D23/$D$4 -> 0
B24: DESPACHO T.M. DEL DIA | D24: =SUM(D5:D23) -> 6031.438
B25: ACUMULADO MES | D25: 123551.92 | E25: =+D25/E2 -> 0.59517853
D26: =+(E2/31)*19 -> 127231.35 | E26: =+D26/E2 -> 0.61290323
D27: =+D25-D26 -> -3679.4348 | E27: =+E25-E26 -> -0.017724699
B29: TEMPORALES
B30: TEMPORAL 1 | C30: 495
B31: TEMPORAL 2 | C31: 1288 | D31: CEMENTO BLANCO 25 Kg. | E31: 13062 | F31: 326.55
B32: MISTI | C32: 675 | D32: CEMENTO BLANCO BIGBAG x 1.5TM | E32: 182 | F32: 273
C33: =+SUM(C30:C32) -> 2458
B35: CARROS
B36: PLAYA | C36: LLAMADO | D36: PROCESO DE C | E36: TOTAL
B37: 19 | C37: 1 | D37: 10 | E37: =+SUM(B37:D37) -> 30
E39: RENDIMIENTO
A40: H1
A41: H2 | B41: 4.6 | C41: 2438 | D41: 3600 | E41: =+C41/D41 -> 0.67722222
A42: H3 | B42: 6.26 | C42: 2777 | D42: 3600 | E42: =+C42/D42 -> 0.77138889
A43: H4 | B43: 13.63 | C43: 2761 | D43: 3900 | E43: =+C43/D43 -> 0.70794872
...

Sheet 20
B1: 45797 | E1: ME MAYO
E2: 207588
B3: DESPACHO DEL DÍA POR TIPO DE CEMENTO | H3: PLAN | I3: REAL | J3: %
D4: =D25 -> 8456.916 | F4: LUNES | G4: 45796 | H4: 6179 | I4: 6031.438 | J4: =+I4/H4 -> 0.97611879
B5: CEM. FRONTERA GU X 42.5 KG | C5: 9363 | D5: 399.658 | E5: =+D5/$D$4 -> 0.047258126 | F5: MARTES | G5: 45797 | H5: 8374 | I5: 8456.916 | J5: =+I5/H5 -> 1.0099016
B6: CEMENTO FRONTERA IP x 42.5 KG | C6: 10345 | D6: 441.594 | E6: =+D6/$D$4 -> 0.052216907 | F6: MIÉRCOLES | G6: 45798 | H6: 7620 | J6: =+I6/H6 -> 0
B7: CEMENTO HS+R X 42.5 KG RUMI | C7: 23222 | D7: 990.61 | E7: =+D7/$D$4 -> 0.11713608 | F7: JUEVES | G7: 45799 | H7: 7440 | J7: =+I7/H7 -> 0
B8: CEMENTO PORTLAND TIPO I X 42.5 KG YURA | C8: 3137 | D8: 133.63 | E8: =+D8/$D$4 -> 0.015801268 | F8: VIERNES | G8: 45800 | H8: 7740 | J8: =+I8/H8 -> 0
B9: CEMENTO YURA ANTISALITRE (MS) X 42.5 KG | C9: =45436+780 -> 46216 | D9: =1939.69+33.282 -> 1972.972 | E9: =+D9/$D$4 -> 0.23329687 | F9: SÁBADO | G9: 45801 | H9: 6194 | J9: =+I9/H9 -> 0
B10: CEMENTO YURA MAX (HS) X 42.5KG | C10: =49869+720 -> 50589 | D10: =2127.228+30.75 -> 2157.978 | E10: =+D10/$D$4 -> 0.25517316 | F10: DOMINGO | G10: 45802 | H10: 4327 | J10: =+I10/H10 -> 0
B11: CEMENTO YURA PRO (HE) 42.5KG | C11: 13420 | D11: 573.014 | E11: =+D11/$D$4 -> 0.067756851 | H11: =+SUM(H4:H5) -> 14553 | I11: =+SUM(I4:I10) -> 14488.354 | J11: =+I11/H11 -> 0.99555789
B12: CEM YURA ESPECIAL (HS) X 42.5 KG | E12: =+D12/$D$4 -> 0
B13: CEMENTO ANTISALITRE TIPO HS x 25KG YURA | E13: =+D13/$D$4 -> 0
B14: CEM. PORT. I BBx1.5TM INC.ENV YURA | E14: =+D14/$D$4 -> 0
B15: CEMENTO YURA PRO (HE) BBx1.5TM INC.ENV | C15: 107 | D15: 161.37 | E15: =+D15/$D$4 -> 0.019081424
B16: CEM ALT REST IN HE BB1.5TM YURA ENV CHIL | C16: =157+22 -> 179 | D16: =236.27+33.19 -> 269.46 | E16: =+D16/$D$4 -> 0.031862679
B17: CEM.YURA ANTISALITRE MS BBx1.5TM INC.ENV | C17: 24 | D17: 36.03 | E17: =+D17/$D$4 -> 0.0042604183
B18: CEMENTO YURA MAX BBx1.5TM INC.ENV | C18: 126 | D18: 189.31 | E18: =+D18/$D$4 -> 0.022385229
B19: CEM. PORT. PUZ. IP BBx1.5TM INC.ENV YURA | C19: 62 | D19: 93.03 | E19: =+D19/$D$4 -> 0.011000464
B20: CEM.ANTISALITRE HS BBx1.5TM INC.ENV YURA | C20: =100+20 -> 120 | D20: =150.81+30.02 -> 180.83 | E20: =+D20/$D$4 -> 0.021382499
B21: FILLER INDUSTRIAL BB1.5TM | C21: 21 | D21: 31.68 | E21: =+D21/$D$4 -> 0.0037460464
B22: CEMENTO YURA PRO (HE) GRANEL EN BOMBONA | D22: 548.26 | E22: =+D22/$D$4 -> 0.06482978
B23: CEMENTO YURA IP A GRANEL EN BOMBONA | D23: 277.49 | E23: =+D23/$D$4 -> 0.032812198
B24: CEMENTO YURA MAX GRANEL BOMBONA | E24: =+D24/$D$4 -> 0
B25: DESPACHO T.M. DEL DIA | D25: =SUM(D5:D24) -> 8456.916
B26: ACUMULADO MES | D26: 132008.84 | E26: =+D26/E2 -> 0.63591747
D27: =+(E2/31)*20 -> 133927.74 | E27: =+D27/E2 -> 0.64516129
D28: =+D26-D27 -> -1918.9059 | E28: =E26-E27 -> -0.0092438192
B30: TEMPORALES
B31: TEMPORAL 1 | C31: 158
B32: TEMPORAL 2 | C32: 1108 | D32: CB 25 Kg. | E32: 15223 | F32: 380.575
B33: MISTI | C33: 479 | D33: CB BIGBAG x 1.5TM | E33: 182 | F33: 273
C34: =+SUM(C31:C33) -> 1745
B36: CARROS
B37: PLAYA | C37: LLAMADO | D37: PROCESO DE C | E37: TOTAL
B38: 30 | C38: 24 | D38: 2 | E38: =+SUM(B38:D38) -> 56
E40: RENDIMIENTO
A41: H1
A42: H2 | B42: 6.99 | C42: 2252 | D42: 3600 | E42: =+C42/D42 -> 0.62555556
A43: H3 | B43: 10.43 | C43: 2872 | D43: 3600 | E43: =+C43/D43 -> 0.79777778
...

Sheet 21
B1: 45798 | E1: ME MAYO
E2: 207588
B3: DESPACHO DEL DÍA POR TIPO DE CEMENTO | H3: PLAN | I3: REAL | J3: %
D4: =D25 -> 7665.696 | F4: LUNES | G4: 45796 | H4: 6179 | I4: 6031.438 | J4: =+I4/H4 -> 0.97611879
B5: CEM. FRONTERA GU X 42.5 KG | C5: 1480 | D5: 63.05 | E5: =+D5/$D$4 -> 0.0082249544 | F5: MARTES | G5: 45797 | H5: 8374 | I5: 8456.916 | J5: =+I5/H5 -> 1.0099016
B6: CEMENTO FRONTERA IP x 42.5 KG | C6: 21790 | D6: 930.058 | E6: =+D6/$D$4 -> 0.12132727 | F6: MIÉRCOLES | G6: 45798 | H6: 7620 | I6: 7665.696 | J6: =+I6/H6 -> 1.0059969
B7: CEMENTO HS+R X 42.5 KG RUMI | C7: 12882 | D7: 549.56 | E7: =+D7/$D$4 -> 0.071690816 | F7: JUEVES | G7: 45799 | H7: 7440 | J7: =+I7/H7 -> 0
B8: CEMENTO PORTLAND TIPO I X 42.5 KG YURA | C8: 4620 | D8: 197.12 | E8: =+D8/$D$4 -> 0.02571456 | F8: VIERNES | G8: 45800 | H8: 7740 | J8: =+I8/H8 -> 0
B9: CEMENTO YURA ANTISALITRE (MS) X 42.5 KG | C9: 27412 | D9: 1169.354 | E9: =+D9/$D$4 -> 0.15254375 | F9: SÁBADO | G9: 45801 | H9: 6194 | J9: =+I9/H9 -> 0
B10: CEMENTO YURA MAX (HS) X 42.5KG | C10: 52254 | D10: 2228.946 | E10: =+D10/$D$4 -> 0.2907689 | F10: DOMINGO | G10: 45802 | H10: 4327 | J10: =+I10/H10 -> 0
B11: CEMENTO YURA PRO (HE) 42.5KG | C11: 10179 | D11: 434.178 | E11: =+D11/$D$4 -> 0.056639084 | H11: =+SUM(H4:H6) -> 22173 | I11: =+SUM(I4:I10) -> 22154.05 | J11: =+I11/H11 -> 0.99914536
B12: CEM YURA ESPECIAL (HS) X 42.5 KG | E12: =+D12/$D$4 -> 0
B13: CEMENTO ANTISALITRE TIPO HS x 25KG YURA | E13: =+D13/$D$4 -> 0
B14: CEM. PORT. I BBx1.5TM INC.ENV YURA | C14: 63 | D14: 95.1 | E14: =+D14/$D$4 -> 0.012405919
B15: CEMENTO YURA PRO (HE) BBx1.5TM INC.ENV | C15: 393 | D15: 591.72 | E15: =+D15/$D$4 -> 0.077190643
B16: CEM ALT REST IN HE BB1.5TM YURA ENV CHIL | C16: 176 | D16: 265.18 | E16: =+D16/$D$4 -> 0.034593075
B17: CEM.YURA ANTISALITRE MS BBx1.5TM INC.ENV | E17: =+D17/$D$4 -> 0
B18: CEMENTO YURA MAX BBx1.5TM INC.ENV | C18: 294 | D18: 441.92 | E18: =+D18/$D$4 -> 0.057649038
B19: CEM. PORT. PUZ. IP BBx1.5TM INC.ENV YURA | E19: =+D19/$D$4 -> 0
B20: CEM.ANTISALITRE HS BBx1.5TM INC.ENV YURA | C20: 40 | D20: 60.2 | E20: =+D20/$D$4 -> 0.0078531682
B21: FILLER INDUSTRIAL BB1.5TM | C21: 22 | D21: 33.07 | E21: =+D21/$D$4 -> 0.0043140245
B22: CEMENTO YURA PRO (HE) GRANEL EN BOMBONA | D22: 304.09 | E22: =+D22/$D$4 -> 0.039668935
B23: CEMENTO YURA IP A GRANEL EN BOMBONA | D23: 213.15 | E23: =+D23/$D$4 -> 0.027805694
B24: CEMENTO YURA MAX GRANEL BOMBONA | D24: 89 | E24: =+D24/$D$4 -> 0.011610166
B25: DESPACHO T.M. DEL DIA | D25: =SUM(D5:D24) -> 7665.696
B26: ACUMULADO MES | D26: 139709.12 | E26: =+D26/E2 -> 0.67301155
D27: =+(E2/31)*21 -> 140624.13 | E27: =+D27/E2 -> 0.67741935
D28: =+D26-D27 -> -915.00703 | E28: =E26-E27 -> -0.0044078031
B30: TEMPORALES
B31: TEMPORAL 1 | C31: 171
B32: TEMPORAL 2 | C32: 981 | D32: CB 25 Kg. | E32: 14755 | F32: 368.875
B33: MISTI | C33: 408 | D33: CB BIGBAG x 1.5TM | E33: 182 | F33: 273
C34: =+SUM(C31:C33) -> 1560
B36: CARROS
B37: PLAYA | C37: LLAMADO | D37: PROCESO DE C | E37: TOTAL
B38: 33 | C38: 1 | D38: 24 | E38: =+SUM(B38:D38) -> 58
E40: RENDIMIENTO
A41: H1
A42: H2 | B42: 11.29 | C42: 2354 | D42: 3600 | E42: =+C42/D42 -> 0.65388889
A43: H3 | B43: 6.36 | C43: 2674 | D43: 3600 | E43: =+C43/D43 -> 0.74277778
...

Sheet 22
B1: =TODAY()-1 -> 46171 | E1: ME MAYO
E2: 207588
B3: DESPACHO DEL DÍA POR TIPO DE CEMENTO | H3: PLAN | I3: REAL | J3: %
D4: =D25 -> 7779.232 | F4: LUNES | G4: 45796 | H4: 6179 | I4: 6031.438 | J4: =+I4/H4 -> 0.97611879
B5: CEM. FRONTERA GU X 42.5 KG | C5: 4600 | D5: 196.312 | E5: =+D5/$D$4 -> 0.025235396 | F5: MARTES | G5: 45797 | H5: 8374 | I5: 8456.916 | J5: =+I5/H5 -> 1.0099016
B6: CEMENTO FRONTERA IP x 42.5 KG | C6: 23154 | D6: 987.748 | E6: =+D6/$D$4 -> 0.12697243 | F6: MIÉRCOLES | G6: 45798 | H6: 7620 | I6: 7665.696 | J6: =+I6/H6 -> 1.0059969
B7: CEMENTO HS+R X 42.5 KG RUMI | C7: 19868 | D7: 847.56 | E7: =+D7/$D$4 -> 0.10895163 | F7: JUEVES | G7: 45799 | H7: 7440 | I7: 7779.232 | J7: =+I7/H7 -> 1.0455957
B8: CEMENTO PORTLAND TIPO I X 42.5 KG YURA | C8: 750 | D8: 32.05 | E8: =+D8/$D$4 -> 0.004119944 | F8: VIERNES | G8: 45800 | H8: 7740 | J8: =+I8/H8 -> 0
B9: CEMENTO YURA ANTISALITRE (MS) X 42.5 KG | C9: 28721 | D9: 1225.034 | E9: =+D9/$D$4 -> 0.15747493 | F9: SÁBADO | G9: 45801 | H9: 6194 | J9: =+I9/H9 -> 0
B10: CEMENTO YURA MAX (HS) X 42.5KG | C10: 47258 | D10: 2013.732 | E10: =+D10/$D$4 -> 0.25886 | F10: DOMINGO | G10: 45802 | H10: 4327 | J10: =+I10/H10 -> 0
B11: CEMENTO YURA PRO (HE) 42.5KG | C11: 13770 | D11: 586.926 | E11: =+D11/$D$4 -> 0.075447808 | H11: =+SUM(H4:H6) -> 22173 | I11: =+SUM(I4:I10) -> 29933.282 | J11: =+I11/H11 -> 1.3499879
B12: CEM YURA ESPECIAL (HS) X 42.5 KG | E12: =+D12/$D$4 -> 0
B13: CEMENTO ANTISALITRE TIPO HS x 25KG YURA | E13: =+D13/$D$4 -> 0
B14: CEM. PORT. I BBx1.5TM INC.ENV YURA | E14: =+D14/$D$4 -> 0
B15: CEMENTO YURA PRO (HE) BBx1.5TM INC.ENV | C15: 322 | D15: 484.18 | E15: =+D15/$D$4 -> 0.062240077
B16: CEM ALT REST IN HE BB1.5TM YURA ENV CHIL | C16: 175 | D16: 263.52 | E16: =+D16/$D$4 -> 0.033874809
B17: CEM.YURA ANTISALITRE MS BBx1.5TM INC.ENV | C17: 22 | D17: 33.05 | E17: =+D17/$D$4 -> 0.0042484914
B18: CEMENTO YURA MAX BBx1.5TM INC.ENV | C18: 289 | D18: 434.77 | E18: =+D18/$D$4 -> 0.05588855
B19: CEM. PORT. PUZ. IP BBx1.5TM INC.ENV YURA | C19: 64 | D19: 96.2 | E19: =+D19/$D$4 -> 0.012366259
B20: CEMENTO BLANCO A GRANEL EN BBx1.5 YURA | C20: 20 | D20: 30.04 | E20: =+D20/$D$4 -> 0.0038615637
B21: FILLER INDUSTRIAL BB1.5TM | E21: =+D21/$D$4 -> 0
B22: CEMENTO YURA PRO (HE) GRANEL EN BOMBONA | D22: 393.95 | E22: =+D22/$D$4 -> 0.050641246
B23: CEMENTO YURA IP A GRANEL EN BOMBONA | D23: 93.6 | E23: =+D23/$D$4 -> 0.012032036
B24: CEMENTO YURA MAX GRANEL BOMBONA | D24: 60.56 | E24: =+D24/$D$4 -> 0.0077848302
B25: DESPACHO T.M. DEL DIA | D25: =SUM(D5:D24) -> 7779.232
B26: ACUMULADO MES | D26: 147488.35 | E26: =+D26/E2 -> 0.71048593
D27: =+(E2/31)*22 -> 147320.52 | E27: =+D27/E2 -> 0.70967742
D28: =+D26-D27 -> 167.83787 | E28: =E26-E27 -> 0.00080851432
B30: TEMPORALES
B31: TEMPORAL 1 | C31: 98
B32: TEMPORAL 2 | C32: 904 | D32: CB 25 Kg. | E32: 14755 | F32: 368.875
B33: MISTI | C33: 477 | D33: CB BIGBAG x 1.5TM | E33: 162 | F33: 243
C34: =+SUM(C31:C33) -> 1479
B36: CARROS
B37: PLAYA | C37: LLAMADO | D37: PROCESO DE C | E37: TOTAL
B38: 33 | C38: 1 | D38: 24 | E38: =+SUM(B38:D38) -> 58
E40: RENDIMIENTO
A41: H1 | F41: Operativos | G41: Módulos
A42: H2 | B42: 13.2 | C42: 2368 | D42: 3600 | E42: =+C42/D42 -> 0.65777778 | F42: 10 | G42: 12
A43: H3 | B43: 4.62 | C43: 2552 | D43: 3600 | E43: =+C43/D43 -> 0.70888889
...

Sheet 25
B1: 45802 | E1: ME MAYO
E2: 207588
B3: DESPACHO DEL DÍA POR TIPO DE CEMENTO | H3: PLAN | I3: REAL | J3: %
D4: =D25 -> 5008.499 | F4: LUNES | G4: 45796 | H4: 6179 | I4: 6031.438 | J4: =+I4/H4 -> 0.97611879
B5: CEMENTO FRONTERA IP x 42.5 KG | C5: 11719 | D5: 500.266 | E5: =+D5/$D$4 -> 0.099883418 | F5: MARTES | G5: 45797 | H5: 8374 | I5: 8456.916 | J5: =+I5/H5 -> 1.0099016
B6: CEMENTO HS+R X 42.5 KG RUMI | C6: 7945 | D6: 339.12 | E6: =+D6/$D$4 -> 0.067708908 | F6: MIÉRCOLES | G6: 45798 | H6: 7620 | I6: 7665.696 | J6: =+I6/H6 -> 1.0059969
B7: CEMENTO PORTLAND TIPO I X 42.5 KG YURA | C7: 8541 | D7: 363.89 | E7: =+D7/$D$4 -> 0.072654502 | F7: JUEVES | G7: 45799 | H7: 7440 | I7: 7779.232 | J7: =+I7/H7 -> 1.0455957
B8: CEMENTO YURA ANTISALITRE (MS) X 42.5 KG | C8: 23403 | D8: 998.284 | E8: =+D8/$D$4 -> 0.199318 | F8: VIERNES | G8: 45800 | H8: 7740 | I8: 8520.68 | J8: =+I8/H8 -> 1.100863
B9: CEMENTO YURA MAX (HS) X 42.5KG | C9: 18556 | D9: 791.914 | E9: =+D9/$D$4 -> 0.15811404 | F9: SÁBADO | G9: 45801 | H9: 6194 | I9: 6660.5 | J9: =+I9/H9 -> 1.0753148
B10: CEMENTO YURA PRO (HE) 42.5KG | C10: 6908 | D10: 294.56 | E10: =+D10/$D$4 -> 0.058812031 | F10: DOMINGO | G10: 45802 | H10: 4327 | I10: 5008.499 | J10: =+I10/H10 -> 1.1574992
B11: CEM. FRONTERA GU X 42.5 KG | C11: 2410 | D11: 102.88 | E11: =+D11/$D$4 -> 0.020541084 | H11: =+SUM(H4:H10) -> 47874 | I11: =+SUM(I4:I10) -> 50122.961 | J11: =+I11/H11 -> 1.0469767
B12: CEM.PORTL.IP(GRADO CORRIENTE)X25KG CHILE | E12: =+D12/$D$4 -> 0
B13: CEM ALT REST IN HE BB1.5TM YURA ENV CHIL | C13: 23 | D13: 34.57 | E13: =+D13/$D$4 -> 0.0069022675
B14: CEM. PORT. PUZ. IP BBx1.5TM INC.ENV YURA | C14: 66 | D14: 99.25 | E14: =+D14/$D$4 -> 0.019816316
B15: CEM.YURA ANTISALITRE MS BBx1.5TM INC.ENV | C15: 31 | D15: 46.545 | E15: =+D15/$D$4 -> 0.0092932034
B16: CEMENTO YURA MAX BBx1.5TM INC.ENV | C16: 97 | D16: 145.95 | E16: =+D16/$D$4 -> 0.029140467
B17: CEMENTO YURA PRO (HE) BBx1.5TM INC.ENV | C17: 194 | D17: 292.18 | E17: =+D17/$D$4 -> 0.058336839
B18: FILLER INDUSTRIAL BB1.5TM | C18: 181 | D18: 272.04 | E18: =+D18/$D$4 -> 0.054315674
B19: CEM. PORT. PUZ. IP BBx1.5TM INC.ENV YURA | E19: =+D19/$D$4 -> 0
B20: CEMENTO BLANCO A GRANEL EN BBx1.5 YURA | E20: =+D20/$D$4 -> 0
B21: FILLER INDUSTRIAL BB1.5TM | E21: =+D21/$D$4 -> 0
B22: CEMENTO YURA IP A GRANEL EN BOMBONA | D22: 277.65 | E22: =+D22/$D$4 -> 0.05543577
B23: CEMENTO YURA MAX GRANEL BOMBONA | D23: 89.14 | E23: =+D23/$D$4 -> 0.017797747
B24: CEMENTO YURA PRO (HE) GRANEL EN BOMBONA | D24: 360.26 | E24: =+D24/$D$4 -> 0.071929734
B25: DESPACHO T.M. DEL DIA | D25: =SUM(D5:D24) -> 5008.499
B26: ACUMULADO MES | D26: 167678.05 | E26: =+D26/E2 -> 0.80774443
D27: =+(E2/31)*25 -> 167409.68 | E27: =+D27/E2 -> 0.80645161
D28: =+D26-D27 -> 268.37258 | E28: =E26-E27 -> 0.0012928136
B30: TEMPORALES
B31: TEMPORAL 1 | C31: 693 | F31: TM
B32: TEMPORAL 2 | C32: 904 | D32: CB 25 Kg. | E32: 15906 | F32: 397.65
B33: MISTI | C33: 1814 | D33: CB BIGBAG x 1.5TM | E33: 162 | F33: 243
C34: =+SUM(C31:C33) -> 3411 | D34: filler | E34: 171 | F34: 256.5
B36: CARROS
B37: PLAYA | C37: LLAMADO | D37: PROCESO DE C | E37: TOTAL
B38: 11 | C38: 2 | D38: 7 | E38: =+SUM(B38:D38) -> 20
E39: RENDIMIENTO
F40: Operativos | G40: Módulos
A41: H1
A42: H2 | B42: 7.91 | C42: 2171 | D42: 3600 | E42: =+C42/D42 -> 0.60305556 | F42: 11 | G42: 12 | H42: Modulo 12
...

Sheet 26
B1: 45803 | E1: ME MAYO
E2: 207588
B3: DESPACHO DEL DÍA POR TIPO DE CEMENTO | H3: PLAN | I3: REAL | J3: %
D4: =D25 -> 6767.674 | F4: LUNES | G4: 45803 | H4: 6960 | I4: 6767.674 | J4: =+I4/H4 -> 0.97236695
B5: CEM. FRONTERA GU X 42.5 KG | C5: 4774 | D5: 203.752 | E5: =+D5/$D$4 -> 0.030106651 | F5: MARTES | G5: 45804 | H5: 8203 | J5: =+I5/H5 -> 0
B6: CEMENTO FRONTERA IP x 42.5 KG | C6: 8364 | D6: 356.82 | E6: =+D6/$D$4 -> 0.052724171 | F6: MIÉRCOLES | G6: 45805 | H6: 8366 | J6: =+I6/H6 -> 0
B7: CEMENTO HS+R X 42.5 KG RUMI | C7: 16082 | D7: 685.88 | E7: =+D7/$D$4 -> 0.10134649 | F7: JUEVES | G7: 45806 | H7: 9206 | J7: =+I7/H7 -> 0
B8: CEMENTO PORTLAND TIPO I X 42.5 KG YURA | C8: 1490 | D8: 63.57 | E8: =+D8/$D$4 -> 0.0093931829 | F8: VIERNES | G8: 45807 | H8: 8287 | J8: =+I8/H8 -> 0
B9: CEMENTO YURA ANTISALITRE (MS) X 42.5 KG | C9: 25524 | D9: 1089.576 | E9: =+D9/$D$4 -> 0.16099712 | F9: SÁBADO | G9: 45808 | H9: 7078 | J9: =+I9/H9 -> 0
B10: CEMENTO YURA MAX (HS) X 42.5KG | C10: 47934 | D10: 2045.209 | E10: =+D10/$D$4 -> 0.30220265 | F10: DOMINGO | G10: 45809 | H10: 4155 | J10: =+I10/H10 -> 0
B11: CEMENTO YURA PRO (HE) 42.5KG | C11: 14165 | D11: 605.062 | E11: =+D11/$D$4 -> 0.08940472 | H11: =+SUM(H4:H10) -> 52255 | I11: =+SUM(I4:I10) -> 6767.674 | J11: =+I11/H11 -> 0.12951247
B12: CEMENTO BLANCO X 25 KG YURA NACIONAL | C12: 1 | D12: 0.025 | E12: =+D12/$D$4 -> 3.6940314e-06
B13: CEM ALT REST IN HE BB1.5TM YURA ENV CHIL | C13: 21 | D13: 31.59 | E13: =+D13/$D$4 -> 0.004667778
B14: CEM. PORT. I BBx1.5TM INC.ENV YURA | C14: 44 | D14: 66.2 | E14: =+D14/$D$4 -> 0.009781795
B15: CEM. PORT. PUZ. IP BBx1.5TM INC.ENV YURA | C15: 22 | D15: 33.16 | E15: =+D15/$D$4 -> 0.0048997632
B16: CEMENTO YURA MAX BBx1.5TM INC.ENV | C16: 211 | D16: 317.36 | E16: =+D16/$D$4 -> 0.046893512
B17: CEMENTO YURA PRO (HE) BBx1.5TM INC.ENV | C17: 278 | D17: 418.58 | E17: =+D17/$D$4 -> 0.061849906
B18: FILLER INDUSTRIAL BB1.5TM | C18: 43 | D18: 64.54 | E18: =+D18/$D$4 -> 0.0095365114
B19: CEM. PORT. PUZ. IP BBx1.5TM INC.ENV YURA | E19: =+D19/$D$4 -> 0
B20: CEMENTO BLANCO A GRANEL EN BBx1.5 YURA | E20: =+D20/$D$4 -> 0
B21: FILLER INDUSTRIAL BB1.5TM | E21: =+D21/$D$4 -> 0
B22: CEMENTO YURA IP A GRANEL EN BOMBONA | D22: 181.15 | E22: =+D22/$D$4 -> 0.026766951
B23: CEMENTO YURA MAX GRANEL BOMBONA | D23: 62.44 | E23: =+D23/$D$4 -> 0.0092262127
B24: CEMENTO YURA PRO (HE) GRANEL EN BOMBONA | D24: 542.76 | E24: =+D24/$D$4 -> 0.080198898
B25: DESPACHO T.M. DEL DIA | D25: =SUM(D5:D24) -> 6767.674
B26: ACUMULADO MES | D26: 174445.72 | E26: =+D26/E2 -> 0.8403459
D27: =+(E2/31)*26 -> 174106.06 | E27: =+D27/E2 -> 0.83870968
D28: =+D26-D27 -> 339.65948 | E28: =E26-E27 -> 0.0016362193
B30: TEMPORALES
B31: TEMPORAL 1 | C31: 874 | F31: TM
B32: TEMPORAL 2 | C32: 1212 | D32: CB 25 Kg. | E32: 15906 | F32: 397.65
B33: MISTI | C33: 1275 | D33: CB BIGBAG x 1.5TM | E33: 162 | F33: 243
C34: =+SUM(C31:C33) -> 3361 | D34: filler | E34: 152 | F34: 228
D35: CEM MICROFISURAS | E35: 31 | F35: 46.5
B36: CARROS
B37: PLAYA | C37: LLAMADO | D37: PROCESO DE C | E37: TOTAL
B38: 21 | C38: 1 | D38: 31 | E38: =+SUM(B38:D38) -> 53
E39: RENDIMIENTO
F40: Operativos | G40: Módulos
A41: H1
...

Sheet 27
B1: 45804 | E1: ME MAYO
E2: 207588
B3: DESPACHO DEL DÍA POR TIPO DE CEMENTO | H3: PLAN | I3: REAL | J3: %
D4: =D25 -> 7584.16 | F4: LUNES | G4: 45803 | H4: 6960 | I4: 6767.674 | J4: =+I4/H4 -> 0.97236695
B5: CEM. FRONTERA GU X 42.5 KG | C5: 4755 | D5: 202.942 | E5: =+D5/$D$4 -> 0.026758665 | F5: MARTES | G5: 45804 | H5: 8203 | I5: 7584.16 | J5: =+I5/H5 -> 0.92455931
B6: CEMENTO FRONTERA IP x 42.5 KG | C6: 11070 | D6: 472.075 | E6: =+D6/$D$4 -> 0.062244863 | F6: MIÉRCOLES | G6: 45805 | H6: 8366 | J6: =+I6/H6 -> 0
B7: CEMENTO HS+R X 42.5 KG RUMI | C7: 14534 | D7: 619.35 | E7: =+D7/$D$4 -> 0.081663625 | F7: JUEVES | G7: 45806 | H7: 9206 | J7: =+I7/H7 -> 0
B8: CEMENTO PORTLAND TIPO I X 42.5 KG YURA | C8: 1545 | D8: 65.89 | E8: =+D8/$D$4 -> 0.0086878441 | F8: VIERNES | G8: 45807 | H8: 8287 | J8: =+I8/H8 -> 0
B9: CEMENTO YURA ANTISALITRE (MS) X 42.5 KG | C9: 35588 | D9: 1518.568 | E9: =+D9/$D$4 -> 0.2002289 | F9: SÁBADO | G9: 45808 | H9: 7078 | J9: =+I9/H9 -> 0
B10: CEMENTO YURA MAX (HS) X 42.5KG | C10: 47462 | D10: 2024.906 | E10: =+D10/$D$4 -> 0.26699147 | F10: DOMINGO | G10: 45809 | H10: 4155 | J10: =+I10/H10 -> 0
B11: CEMENTO YURA PRO (HE) 42.5KG | C11: 11309 | D11: 482.759 | E11: =+D11/$D$4 -> 0.063653589 | H11: =+SUM(H4:H5) -> 15163 | I11: =+SUM(I4:I10) -> 14351.834 | J11: =+I11/H11 -> 0.94650359
B12: CEMENTO BLANCO X 25 KG YURA NACIONAL | E12: =+D12/$D$4 -> 0
B13: CEM. PORT. PUZ. IP BBx1.5TM INC.ENV YURA | C13: 83 | D13: 124.84 | E13: =+D13/$D$4 -> 0.016460623
B14: CEM.ANTISALITRE HS BBx1.5TM INC.ENV YURA | C14: 20 | D14: 30.13 | E14: =+D14/$D$4 -> 0.0039727537
B15: CEM.YURA ANTISALITRE MS BBx1.5TM INC.ENV | C15: 24 | D15: 36.06 | E15: =+D15/$D$4 -> 0.0047546465
B16: CEMENTO YURA MAX BBx1.5TM INC.ENV | C16: 150 | D16: 225.73 | E16: =+D16/$D$4 -> 0.029763349
B17: CEMENTO YURA PRO (HE) BBx1.5TM INC.ENV | C17: 634 | D17: 954.09 | E17: =+D17/$D$4 -> 0.12580035
B18: FILLER INDUSTRIAL BB1.5TM | C18: 44 | D18: 66.19 | E18: =+D18/$D$4 -> 0.0087274003
B19: CEM. PORT. PUZ. IP BBx1.5TM INC.ENV YURA | E19: =+D19/$D$4 -> 0
B20: CEMENTO BLANCO A GRANEL EN BBx1.5 YURA | E20: =+D20/$D$4 -> 0
B21: FILLER INDUSTRIAL BB1.5TM | E21: =+D21/$D$4 -> 0
B22: CEMENTO YURA IP A GRANEL EN BOMBONA | D22: 210.9 | E22: =+D22/$D$4 -> 0.027807958
B23: CEMENTO YURA MAX GRANEL BOMBONA | D23: 89.12 | E23: =+D23/$D$4 -> 0.011750807
B24: CEMENTO YURA PRO (HE) GRANEL EN BOMBONA | D24: 460.61 | E24: =+D24/$D$4 -> 0.06073316
B25: DESPACHO T.M. DEL DIA | D25: =SUM(D5:D24) -> 7584.16
B26: ACUMULADO MES | D26: 182388.46 | E26: =+D26/E2 -> 0.87860793
D27: =+(E2/31)*27 -> 180802.45 | E27: =+D27/E2 -> 0.87096774
D28: =+D26-D27 -> 1586.0104 | E28: =E26-E27 -> 0.0076401834
B30: TEMPORALES
B31: TEMPORAL 1 | C31: 565 | F31: TM
B32: TEMPORAL 2 | C32: 1169 | D32: CB 25 Kg. | E32: 15906 | F32: 397.65
B33: MISTI | C33: 433 | D33: CB BIGBAG x 1.5TM | E33: 162 | F33: 243
C34: =+SUM(C31:C33) -> 2167 | D34: filler | E34: 152 | F34: 228
D35: CEM MICROFISURAS | E35: 31 | F35: 46.5
B36: CARROS
B37: PLAYA | C37: LLAMADO | D37: PROCESO DE C | E37: TOTAL
B38: 30 | C38: 0 | D38: 15 | E38: =+SUM(B38:D38) -> 45
E39: RENDIMIENTO
F40: Operativos | G40: Falla
A41: H1
...

Sheet 28
B1: 45805 | E1: ME MAYO
E2: 207588
B3: DESPACHO DEL DÍA POR TIPO DE CEMENTO | H3: PLAN | I3: REAL | J3: %
D4: =D22 -> 8183.152 | F4: LUNES | G4: 45803 | H4: 6960 | I4: 6767.674 | J4: =+I4/H4 -> 0.97236695
B5: CEM. FRONTERA GU X 42.5 KG | C5: 6320 | D5: 270.004 | E5: =+D5/$D$4 -> 0.03299511 | F5: MARTES | G5: 45804 | H5: 8203 | I5: 7584.16 | J5: =+I5/H5 -> 0.92455931
B6: CEMENTO FRONTERA IP x 42.5 KG | C6: 19830 | D6: 845.58 | E6: =+D6/$D$4 -> 0.10333182 | F6: MIÉRCOLES | G6: 45805 | H6: 8366 | I6: 8183.152 | J6: =+I6/H6 -> 0.97814392
B7: CEMENTO HS+R X 42.5 KG RUMI | C7: 14533 | D7: 619.856 | E7: =+D7/$D$4 -> 0.075747829 | F7: JUEVES | G7: 45806 | H7: 9206 | J7: =+I7/H7 -> 0
B8: CEMENTO PORTLAND TIPO I X 42.5 KG YURA | C8: 2990 | D8: 127.52 | E8: =+D8/$D$4 -> 0.015583237 | F8: VIERNES | G8: 45807 | H8: 8287 | J8: =+I8/H8 -> 0
B9: CEMENTO YURA ANTISALITRE (MS) X 42.5 KG | C9: 36927 | D9: 1575.046 | E9: =+D9/$D$4 -> 0.19247424 | F9: SÁBADO | G9: 45808 | H9: 7078 | J9: =+I9/H9 -> 0
B10: CEMENTO YURA MAX (HS) X 42.5KG | C10: 51791 | D10: 2210.304 | E10: =+D10/$D$4 -> 0.27010423 | F10: DOMINGO | G10: 45809 | H10: 4155 | J10: =+I10/H10 -> 0
B11: CEMENTO YURA PRO (HE) 42.5KG | C11: 14170 | D11: 604.471 | E11: =+D11/$D$4 -> 0.073867747 | H11: =+SUM(H4:H6) -> 23529 | I11: =+SUM(I4:I10) -> 22534.986 | J11: =+I11/H11 -> 0.95775367
B12: CEMENTO BLANCO X 25 KG YURA NACIONAL | C12: 1202 | D12: 30.29 | E12: =+D12/$D$4 -> 0.0037015077
B13: CEM. PORT. I BBx1.5TM INC.ENV YURA | C13: 22 | D13: 33.11 | E13: =+D13/$D$4 -> 0.0040461182
B14: CEMENTO YURA PRO (HE) BBx1.5TM INC.ENV | C14: 436 | D14: 656.17 | E14: =+D14/$D$4 -> 0.080185484
B15: CEM. PORT. PUZ. IP BBx1.5TM INC.ENV YURA | C15: 21 | D15: 31.55 | E15: =+D15/$D$4 -> 0.0038554826
B16: CEM.ANTISALITRE HS BBx1.5TM INC.ENV YURA | C16: 100 | D16: 150.47 | E16: =+D16/$D$4 -> 0.01838778
B17: CEMENTO YURA MAX BBx1.5TM INC.ENV | C17: 229 | D17: 344.75 | E17: =+D17/$D$4 -> 0.042129243
B18: CEMENTO PARA MICROFISURAS BIGBAG X1.5 TM | C18: 10 | D18: 15.081 | E18: =+D18/$D$4 -> 0.0018429329
B19: CEMENTO YURA PRO (HE) GRANEL EN BOMBONA | D19: 457.27 | E19: =+D19/$D$4 -> 0.055879446
B20: CEMENTO YURA IP A GRANEL EN BOMBONA | D20: 151.95 | E20: =+D20/$D$4 -> 0.01856864
B21: CEMENTO YURA MAX GRANEL BOMBONA | D21: 59.73 | E21: =+D21/$D$4 -> 0.0072991434
B22: DESPACHO T.M. DEL DIA | D22: =SUM(D5:D21) -> 8183.152
B23: ACUMULADO MES | D23: 191494.1 | E23: =+D23/$E$2 -> 0.92247192
D24: =+(E2/31)*28 -> 187498.84 | E24: =+D24/E2 -> 0.90322581
D25: =+D23-D24 -> 3995.2613 | E25: =+E23-E24 -> 0.019246109
B27: TEMPORALES
B28: TEMPORAL 1 | C28: 435 | F28: TM
B29: TEMPORAL 2 | C29: 1074 | D29: CB 25 Kg. | E29: 14668 | F29: 366.7
B30: MISTI | C30: 773 | D30: CB BIGBAG x 1.5TM | E30: 167 | F30: 250.5
C31: =+SUM(C28:C30) -> 2282 | D31: filler | E31: 108 | F31: 162
D32: CEM MICROFISURAS | E32: 20 | F32: 30
B33: CARROS
B34: PLAYA | C34: LLAMADO | D34: PROCESO DE C | E34: TOTAL
B35: 7 | C35: 3 | D35: 20 | E35: =+SUM(B35:D35) -> 30
E36: RENDIMIENTO
F37: Operativos | G37: Falla
A38: H1
A39: H2 | B39: 9.52 | C39: 2283 | D39: 3600 | E39: =+C39/D39 -> 0.63416667 | F39: 12
A40: H3 | B40: 7.47 | C40: 3174 | D40: 3600 | E40: =+C40/D40 -> 0.88166667 | F40: 12
A41: H4 | B41: 15.9 | C41: 2957 | D41: 3900 | E41: =+C41/D41 -> 0.75820513 | F41: 11 | G41: 1
...

Sheet 29
B1: 45806 | E1: ME MAYO
E2: 207588
B3: DESPACHO DEL DÍA POR TIPO DE CEMENTO | H3: PLAN | I3: REAL | J3: %
D4: =D21 -> 7689.895 | F4: LUNES | G4: 45803 | H4: 6960 | I4: 6767.674 | J4: =+I4/H4 -> 0.97236695
B5: CEM. FRONTERA GU X 42.5 KG | C5: 3840 | D5: 163.874 | E5: =+D5/$D$4 -> 0.021310304 | F5: MARTES | G5: 45804 | H5: 8203 | I5: 7584.16 | J5: =+I5/H5 -> 0.92455931
B6: CEMENTO FRONTERA IP x 42.5 KG | C6: 12493 | D6: 533.112 | E6: =+D6/$D$4 -> 0.069326304 | F6: MIÉRCOLES | G6: 45805 | H6: 8366 | I6: 8183.152 | J6: =+I6/H6 -> 0.97814392
B7: CEMENTO HS+R X 42.5 KG RUMI | C7: 24477 | D7: 1043.11 | E7: =+D7/$D$4 -> 0.13564685 | F7: JUEVES | G7: 45806 | H7: 9206 | I7: 7689.895 | J7: =+I7/H7 -> 0.83531338
B8: CEMENTO PORTLAND TIPO I X 42.5 KG YURA | C8: 2470 | D8: 105.11 | E8: =+D8/$D$4 -> 0.013668587 | F8: VIERNES | G8: 45807 | H8: 8287 | J8: =+I8/H8 -> 0
B9: CEMENTO YURA ANTISALITRE (MS) X 42.5 KG | C9: 33460 | D9: 1427.556 | E9: =+D9/$D$4 -> 0.18564051 | F9: SÁBADO | G9: 45808 | H9: 7078 | J9: =+I9/H9 -> 0
B10: CEMENTO YURA MAX (HS) X 42.5KG | C10: 46452 | D10: 1982.677 | E10: =+D10/$D$4 -> 0.25782888 | F10: DOMINGO | G10: 45809 | H10: 4155 | J10: =+I10/H10 -> 0
B11: CEMENTO YURA PRO (HE) 42.5KG | C11: 8500 | D11: 362.932 | E11: =+D11/$D$4 -> 0.047195963 | H11: =+SUM(H4:H7) -> 32735 | I11: =+SUM(I4:I10) -> 30224.881 | J11: =+I11/H11 -> 0.92332002
B12: CEMENTO BLANCO X 25 KG YURA NACIONAL | C12: 1200 | D12: 30.204 | E12: =+D12/$D$4 -> 0.0039277519
B13: CEM. PORT. I BBx1.5TM INC.ENV YURA | C13: 22 | D13: 33.04 | E13: =+D13/$D$4 -> 0.0042965476
B14: CEMENTO YURA PRO (HE) BBx1.5TM INC.ENV | C14: 582 | D14: 875.55 | E14: =+D14/$D$4 -> 0.11385721
B15: CEM ALT REST IN HE BB1.5TM YURA ENV CHIL | C15: 88 | D15: 132.24 | E15: =+D15/$D$4 -> 0.017196594
B16: CEM. PORT. PUZ. IP BBx1.5TM INC.ENV YURA | C16: 20 | D16: 30.14 | E16: =+D16/$D$4 -> 0.0039194293
B17: CEMENTO YURA MAX BBx1.5TM INC.ENV | C17: 184 | D17: 277 | E17: =+D17/$D$4 -> 0.036021298
B18: CEMENTO YURA PRO (HE) GRANEL EN BOMBONA | D18: 422.95 | E18: =+D18/$D$4 -> 0.055000751
B19: CEMENTO YURA IP A GRANEL EN BOMBONA | D19: 211.01 | E19: =+D19/$D$4 -> 0.027439907
B20: CEMENTO YURA MAX GRANEL BOMBONA | D20: 59.39 | E20: =+D20/$D$4 -> 0.0077231224
B21: DESPACHO T.M. DEL DIA | D21: =SUM(D5:D20) -> 7689.895 | E21: =+D21/$D$4 -> 1
B22: ACUMULADO MES | D22: 199183.99 | E22: =+D22/$E$2 -> 0.95951594
D23: =+(E2/31)*29 -> 194195.23 | E23: =+D23/E2 -> 0.93548387
D24: =+D22-D23 -> 4988.7692 | E24: =+E22-E23 -> 0.024032069
B26: TEMPORALES
B27: TEMPORAL 1 | C27: 1093 | F27: TM
B28: TEMPORAL 2 | C28: 1070 | D28: CB 25 Kg. | E28: 13468 | F28: 336.7
B29: MISTI | C29: 834 | D29: CB BIGBAG x 1.5TM | E29: 167 | F29: 250.5
C30: =+SUM(C27:C29) -> 2997 | D30: filler | E30: 108 | F30: 162
D31: CEM MICROFISURAS | E31: 20 | F31: 30
B32: CARROS
B33: PLAYA | C33: LLAMADO | D33: PROCESO DE C | E33: TOTAL
B34: 23 | C34: 2 | D34: 13 | E34: =+SUM(B34:D34) -> 38
E35: RENDIMIENTO
F36: Operativos | G36: Falla
A37: H1
A38: H2 | B38: 9.27 | C38: 1989 | D38: 3600 | E38: =+C38/D38 -> 0.5525 | F38: 12
A39: H3 | B39: 10.76 | C39: 2909 | D39: 3600 | E39: =+C39/D39 -> 0.80805556 | F39: 12
A40: H4 | B40: 15.34 | C40: 2943 | D40: 3900 | E40: =+C40/D40 -> 0.75461538 | F40: 11 | G40: 1
A41: H5 | B41: 16.84 | C41: 2680 | D41: 3900 | E41: =+C41/D41 -> 0.68717949 | F41: 11 | G41: 6
...

Sheet 01.06
B1: 45809 | E1: ME JUNIO
E2: 204590
B3: DESPACHO DEL DÍA POR TIPO DE CEMENTO | H3: PLAN | I3: REAL | J3: %
D4: =D25 -> 5160.689 | F4: LUNES | G4: 45803 | H4: 6960 | I4: 6767.674 | J4: =+I4/H4 -> 0.97236695
B5: CEM. FRONTERA GU X 42.5 KG | E5: =+D5/$D$4 -> 0 | F5: MARTES | G5: 45804 | H5: 8203 | I5: 7584.16 | J5: =+I5/H5 -> 0.92455931
B6: CEMENTO FRONTERA IP x 42.5 KG | C6: 6830 | D6: 291.79 | E6: =+D6/$D$4 -> 0.0565409 | F6: MIÉRCOLES | G6: 45805 | H6: 8366 | I6: 8183.152 | J6: =+I6/H6 -> 0.97814392
B7: CEMENTO HS+R X 42.5 KG RUMI | C7: 20199 | D7: 862.49 | E7: =+D7/$D$4 -> 0.16712691 | F7: JUEVES | G7: 45806 | H7: 9206 | I7: 7689.895 | J7: =+I7/H7 -> 0.83531338
B8: CEMENTO PORTLAND TIPO I X 42.5 KG YURA | C8: 1885 | D8: 80.346 | E8: =+D8/$D$4 -> 0.015568851 | F8: VIERNES | G8: 45807 | H8: 8287 | I8: 7006.09 | J8: =+I8/H8 -> 0.8454314
B9: CEMENTO YURA ANTISALITRE (MS) X 42.5 KG | C9: 12149 | D9: 518.444 | E9: =+D9/$D$4 -> 0.10046023 | F9: SÁBADO | G9: 45808 | H9: 7078 | I9: 6039.93 | J9: =+I9/H9 -> 0.85333851
B10: CEMENTO YURA MAX (HS) X 42.5KG | C10: 34819 | D10: 1487.073 | E10: =+D10/$D$4 -> 0.28815397 | F10: DOMINGO | G10: 45809 | H10: 4155 | I10: 5160.689 | J10: =+I10/H10 -> 1.2420431
B11: CEMENTO YURA PRO (HE) 42.5KG | C11: 8555 | D11: 364.874 | E11: =+D11/$D$4 -> 0.070702575 | H11: =+SUM(H4:H10) -> 52255 | I11: =+SUM(I4:I10) -> 48431.59 | J11: =+I11/H11 -> 0.92683169
B12: CEM.PORTL.IP(GRADO CORRIENTE)X25KG CHILE | C12: 13743 | D12: 348.376 | E12: =+D12/$D$4 -> 0.067505715
B13: CEMENTO PARA ACABADOS TIPO MH 25KG YURA | C13: 1224 | D13: 30.906 | E13: =+D13/$D$4 -> 0.0059887352
B14: CEM. PORT. I BBx1.5TM INC.ENV YURA | C14: 20 | D14: 30.21 | E14: =+D14/$D$4 -> 0.0058538695 | F14: MAYO
B15: CEMENTO YURA PRO (HE) BBx1.5TM INC.ENV | C15: 130 | D15: 196 | E15: =+D15/$D$4 -> 0.037979425 | F15: REAL | G15: 212393.17 | H15: TM
B16: CEM ALT REST IN HE BB1.5TM YURA ENV CHIL | E16: =+D16/$D$4 -> 0 | F16: ME | G16: 207588 | H16: TM
B17: CEM.ANTISALITRE HS BBx1.5TM INC.ENV YURA | C17: 40 | D17: 60.32 | E17: =+D17/$D$4 -> 0.011688362 | G17: =+G15/G16 -> 1.0231476
B18: CEM. PORT. PUZ. IP BBx1.5TM INC.ENV YURA | C18: 44 | D18: 66.2 | E18: =+D18/$D$4 -> 0.012827745 | G18: =+G15-G16 -> 4805.173 | H18: TM
B19: CEMENTO YURA MAX BBx1.5TM INC.ENV | C19: 121 | D19: 182.38 | E19: =+D19/$D$4 -> 0.035340242
B20: CEM.YURA ANTISALITRE MS BBx1.5TM INC.ENV | E20: =+D20/$D$4 -> 0
B21: FILLER INDUSTRIAL BB1.5TM | C21: 244 | D21: 367.83 | E21: =+D21/$D$4 -> 0.071275367
B22: CEMENTO YURA PRO (HE) GRANEL EN BOMBONA | D22: 181.52 | E22: =+D22/$D$4 -> 0.035173598
B23: CEMENTO YURA IP A GRANEL EN BOMBONA | D23: 91.93 | E23: =+D23/$D$4 -> 0.017813513
B24: CEMENTO YURA MAX GRANEL BOMBONA | E24: =+D24/$D$4 -> 0
B25: DESPACHO T.M. DEL DIA | D25: =SUM(D5:D24) -> 5160.689
B26: ACUMULADO MES | D26: 5160.689 | E26: =+D26/E2 -> 0.025224542
D27: =+(E2/30)*1 -> 6819.6667 | E27: =+D27/E2 -> 0.033333333
D28: =+D26-D27 -> -1658.9777 | E28: =+E26-E27 -> -0.0081087916
B30: TEMPORALES | D30: Capacidad ™ | E30: % | I30: TM
B31: TEMPORAL 1 | C31: 1548 | D31: 2142 | E31: =+C31/D31 -> 0.72268908 | G31: CB 25 Kg. | H31: 14233 | I31: 355.825
B32: TEMPORAL 2 | C32: 1727 | D32: 1890 | E32: =+C32/D32 -> 0.91375661 | G32: CB 25 Kg. PINGÜINO | H32: 1086 | I32: 27.15
B33: MISTI | C33: 1105 | D33: 3006 | E33: =+C33/D33 -> 0.36759814 | G33: CB BIGBAG x 1.5TM | H33: 205 | I33: 307.5
C34: =+SUM(C31:C33) -> 4380 | D34: =+SUM(D31:D33) -> 7038 | G34: filler | H34: 30 | I34: 45
G35: CEM MICROFISURAS | H35: 20 | I35: 34.5
B36: CARROS
B37: PLAYA | C37: LLAMADO | D37: PROCESO DE C | E37: TOTAL
B38: 5 | C38: 0 | D38: 1 | E38: =+SUM(B38:D38) -> 6
E39: RENDIMIENTO
F40: Operativos | G40: Falla
A41: H1 | B41: 0.7 | C41: 2243 | D41: 2400 | E41: =+C41/D41 -> 0.93458333 | F41: 7
...

Sheet 02.06
B1: =TODAY()-1 -> 46171 | E1: ME JUNIO
E2: 204590
B3: DESPACHO DEL DÍA POR TIPO DE CEMENTO | H3: PLAN | I3: REAL | J3: %
D4: =D25 -> 6545.779 | F4: LUNES | G4: 45810 | H4: 7474 | I4: 6545.779 | J4: =+I4/H4 -> 0.87580666
B5: CEM. FRONTERA GU X 42.5 KG | C5: 1540 | D5: 65.9 | E5: =+D5/$D$4 -> 0.010067557 | F5: MARTES | G5: 45811 | H5: 8291 | J5: =+I5/H5 -> 0
B6: CEMENTO FRONTERA IP x 42.5 KG | C6: 10255 | D6: 438.15 | E6: =+D6/$D$4 -> 0.066936265 | F6: MIÉRCOLES | G6: 45812 | H6: 7668 | J6: =+I6/H6 -> 0
B7: CEMENTO HS+R X 42.5 KG RUMI | C7: 15271 | D7: 651.57 | E7: =+D7/$D$4 -> 0.099540483 | F7: JUEVES | G7: 45813 | H7: 8120 | J7: =+I7/H7 -> 0
B8: CEMENTO PORTLAND TIPO I X 42.5 KG YURA | C8: 1520 | D8: 64.88 | E8: =+D8/$D$4 -> 0.0099117309 | F8: VIERNES | G8: 45814 | H8: 7820 | J8: =+I8/H8 -> 0
B9: CEMENTO YURA ANTISALITRE (MS) X 42.5 KG | C9: 27217 | D9: 1161.255 | E9: =+D9/$D$4 -> 0.17740516 | F9: SÁBADO | G9: 45815 | H9: 6286 | J9: =+I9/H9 -> 0
B10: CEMENTO YURA MAX (HS) X 42.5KG | C10: 35287 | D10: 1507.128 | E10: =+D10/$D$4 -> 0.23024425 | F10: DOMINGO | G10: 45816 | H10: 3782 | J10: =+I10/H10 -> 0
B11: CEMENTO YURA PRO (HE) 42.5KG | C11: 13238 | D11: 564.944 | E11: =+D11/$D$4 -> 0.086306611 | H11: =+SUM(H4:H10) -> 49441 | I11: =+SUM(I4:I10) -> 6545.779 | J11: =+I11/H11 -> 0.13239576
B12: CEM.PORTL.IP(GRADO CORRIENTE)X25KG CHILE | C12: 5426 | D12: 137.074 | E12: =+D12/$D$4 -> 0.020940823
B13: CEMENTO BLANCO X 25 KG YURA NACIONAL | C13: 250 | D13: 6.298 | E13: =+D13/$D$4 -> 0.00096214675
B14: CEM. PORT. I BBx1.5TM INC.ENV YURA | C14: 44 | D14: 66.56 | E14: =+D14/$D$4 -> 0.010168385 | F14: MAYO
B15: CEMENTO YURA PRO (HE) BBx1.5TM INC.ENV | C15: 417 | D15: 628.96 | E15: =+D15/$D$4 -> 0.096086348 | F15: REAL | G15: 212393.17 | H15: TM
B16: CEM ALT REST IN HE BB1.5TM YURA ENV CHIL | C16: 224 | D16: 338.09 | E16: =+D16/$D$4 -> 0.051650079 | F16: ME | G16: 207588 | H16: TM
B17: CEM.ANTISALITRE HS BBx1.5TM INC.ENV YURA | E17: =+D17/$D$4 -> 0 | G17: =+G15/G16 -> 1.0231476
B18: CEM. PORT. PUZ. IP BBx1.5TM INC.ENV YURA | C18: 21 | D18: 31.56 | E18: =+D18/$D$4 -> 0.0048214277 | G18: =+G15-G16 -> 4805.173 | H18: TM
B19: CEMENTO YURA MAX BBx1.5TM INC.ENV | C19: 146 | D19: 219.44 | E19: =+D19/$D$4 -> 0.033523894 | H19: 2024 | I19: 2025
B20: CEM.YURA ANTISALITRE MS BBx1.5TM INC.ENV | E20: =+D20/$D$4 -> 0 | G20: ENERO | H20: 204007.8 | I20: 190629.13 | J20: =+I20/H20 -> 0.93442077
B21: CEMENTO BLANCO A GRANEL EN BBx1.5 YURA | C21: 20 | D21: 30.03 | E21: =+D21/$D$4 -> 0.0045876893 | G21: FEBRERO | H21: 186305.94 | I21: 182874.29 | J21: =+I21/H21 -> 0.98158052
B22: CEMENTO YURA PRO (HE) GRANEL EN BOMBONA | D22: 329.33 | E22: =+D22/$D$4 -> 0.050311812 | G22: MARZO | H22: 199570.19 | I22: 197224.22 | J22: =+I22/H22 -> 0.98824488
B23: CEMENTO YURA IP A GRANEL EN BOMBONA | D23: 214.79 | E23: =+D23/$D$4 -> 0.032813512 | G23: ABRIL | H23: 205343.73 | I23: 198970.76 | J23: =+I23/H23 -> 0.96896438
B24: CEMENTO YURA MAX GRANEL BOMBONA | D24: 89.82 | E24: =+D24/$D$4 -> 0.01372182 | G24: MAYO | H24: 209473.77 | I24: 212393.17 | J24: =+I24/H24 -> 1.0139368
B25: DESPACHO T.M. DEL DIA | D25: =SUM(D5:D24) -> 6545.779 | H25: =+SUM(H20:H24) -> 1004701.4 | I25: =+SUM(I20:I24) -> 982091.56 | J25: =+I25/H25 -> 0.97749593
B26: ACUMULADO MES | D26: 11706.468 | E26: =+D26/E2 -> 0.05721916
D27: =+(E2/30)*2 -> 13639.333 | E27: =+D27/E2 -> 0.066666667
D28: =+D26-D27 -> -1932.8653 | E28: =+E26-E27 -> -0.0094475064
B30: TEMPORALES | D30: Capacidad ™ | E30: % | I30: TM
B31: TEMPORAL 1 | C31: 439 | D31: 2142 | E31: =+C31/D31 -> 0.20494865 | G31: CB 25 Kg. | H31: 14233 | I31: 355.825
B32: TEMPORAL 2 | C32: 1384 | D32: 1890 | E32: =+C32/D32 -> 0.73227513 | G32: CB 25 Kg. PINGÜINO | H32: 1086 | I32: 27.15
B33: MISTI | C33: 539 | D33: 3006 | E33: =+C33/D33 -> 0.17930805 | G33: CB BIGBAG x 1.5TM | H33: 185 | I33: 277.5
C34: =+SUM(C31:C33) -> 2362 | D34: =+SUM(D31:D33) -> 7038 | G34: filler | H34: 30 | I34: 45
G35: CEM MICROFISURAS | H35: 23 | I35: 34.5
B36: CARROS | G36: CARBONATO 1.5 | H36: 56 | I36: 84
B37: PLAYA | C37: LLAMADO | D37: PROCESO DE C | E37: TOTAL
B38: 15 | C38: 0 | D38: 27 | E38: =+SUM(B38:D38) -> 42
E39: RENDIMIENTO
F40: Operativos | G40: Falla
A41: H1 | B41: 0 | C41: 2243 | D41: 2400 | E41: =+C41/D41 -> 0.93458333 | F41: 7
...

Sheet 03.06
B1: 45811 | E1: ME JUNIO
E2: 204590
B3: DESPACHO DEL DÍA POR TIPO DE CEMENTO | H3: PLAN | I3: REAL | J3: %
D4: =D25 -> 8122.253 | F4: LUNES | G4: 45810 | H4: 7474 | I4: 6545.779 | J4: =+I4/H4 -> 0.87580666
B5: CEM. FRONTERA GU X 42.5 KG | C5: 6162 | D5: 263.25 | E5: =+D5/$D$4 -> 0.032410958 | F5: MARTES | G5: 45811 | H5: 8291 | I5: 8122.253 | J5: =+I5/H5 -> 0.97964697
B6: CEMENTO FRONTERA IP x 42.5 KG | C6: 6320 | D6: 270.05 | E6: =+D6/$D$4 -> 0.033248164 | F6: MIÉRCOLES | G6: 45812 | H6: 7668 | J6: =+I6/H6 -> 0
B7: CEMENTO HS+R X 42.5 KG RUMI | C7: 19749 | D7: 843.484 | E7: =+D7/$D$4 -> 0.10384853 | F7: JUEVES | G7: 45813 | H7: 8120 | J7: =+I7/H7 -> 0
B8: CEMENTO PORTLAND TIPO I X 42.5 KG YURA | C8: 4070 | D8: 173.48 | E8: =+D8/$D$4 -> 0.021358606 | F8: VIERNES | G8: 45814 | H8: 7820 | J8: =+I8/H8 -> 0
B9: CEMENTO YURA ANTISALITRE (MS) X 42.5 KG | C9: 40610 | D9: 1732.434 | E9: =+D9/$D$4 -> 0.21329476 | F9: SÁBADO | G9: 45815 | H9: 6286 | J9: =+I9/H9 -> 0
B10: CEMENTO YURA MAX (HS) X 42.5KG | C10: 44850 | D10: 1916.306 | E10: =+D10/$D$4 -> 0.23593281 | F10: DOMINGO | G10: 45816 | H10: 3782 | J10: =+I10/H10 -> 0
B11: CEMENTO YURA PRO (HE) 42.5KG | C11: 11570 | D11: 494.219 | E11: =+D11/$D$4 -> 0.060847526 | H11: =+SUM(H4:H10) -> 49441 | I11: =+SUM(I4:I10) -> 14668.032 | J11: =+I11/H11 -> 0.29667749
B12: CEM.PORTL.IP(GRADO CORRIENTE)X25KG CHILE | E12: =+D12/$D$4 -> 0
B13: CEMENTO BLANCO X 25 KG YURA NACIONAL | E13: =+D13/$D$4 -> 0
B14: CEM. PORT. I BBx1.5TM INC.ENV YURA | C14: 69 | D14: 104.33 | E14: =+D14/$D$4 -> 0.012844958 | F14: MAYO
B15: CEMENTO YURA PRO (HE) BBx1.5TM INC.ENV | C15: 387 | D15: 584.02 | E15: =+D15/$D$4 -> 0.071903695 | F15: REAL | G15: 212393.17 | H15: TM
B16: CEM ALT REST IN HE BB1.5TM YURA ENV CHIL | C16: 273 | D16: 412.37 | E16: =+D16/$D$4 -> 0.050770396 | F16: ME | G16: 207588 | H16: TM
B17: CEM.ANTISALITRE HS BBx1.5TM INC.ENV YURA | E17: =+D17/$D$4 -> 0 | G17: =+G15/G16 -> 1.0231476
B18: CEM. PORT. PUZ. IP BBx1.5TM INC.ENV YURA | C18: 106 | D18: 159.38 | E18: =+D18/$D$4 -> 0.019622634 | G18: =+G15-G16 -> 4805.173 | H18: TM
B19: CEMENTO YURA MAX BBx1.5TM INC.ENV | C19: 189 | D19: 284.25 | E19: =+D19/$D$4 -> 0.034996447 | H19: 2024 | I19: 2025
B20: CEM.YURA ANTISALITRE MS BBx1.5TM INC.ENV | C20: 22 | D20: 33 | E20: =+D20/$D$4 -> 0.0040629121 | G20: ENERO | H20: 204007.8 | I20: 190629.13 | J20: =+I20/H20 -> 0.93442077
B21: CEMENTO BLANCO A GRANEL EN BBx1.5 YURA | D21: 29.53 | E21: =+D21/$D$4 -> 0.0036356907 | G21: FEBRERO | H21: 186305.94 | I21: 182874.29 | J21: =+I21/H21 -> 0.98158052
B22: CEMENTO YURA PRO (HE) GRANEL EN BOMBONA | D22: 545.47 | E22: =+D22/$D$4 -> 0.067157475 | G22: MARZO | H22: 199570.19 | I22: 197224.22 | J22: =+I22/H22 -> 0.98824488
B23: CEMENTO YURA IP A GRANEL EN BOMBONA | D23: 215.84 | E23: =+D23/$D$4 -> 0.026573908 | G23: ABRIL | H23: 205343.73 | I23: 198970.76 | J23: =+I23/H23 -> 0.96896438
B24: CEMENTO YURA MAX GRANEL BOMBONA | D24: 60.84 | E24: =+D24/$D$4 -> 0.0074905325 | G24: MAYO | H24: 209473.77 | I24: 212393.17 | J24: =+I24/H24 -> 1.0139368
B25: DESPACHO T.M. DEL DIA | D25: =SUM(D5:D24) -> 8122.253 | H25: =+SUM(H20:H24) -> 1004701.4 | I25: =+SUM(I20:I24) -> 982091.56 | J25: =+I25/H25 -> 0.97749593
B26: ACUMULADO MES | D26: 19828.721 | E26: =+D26/E2 -> 0.096919307
D27: =+(E2/30)*3 -> 20459 | E27: =+D27/E2 -> 0.1 | I27: TM
D28: =+D26-D27 -> -630.279 | E28: =+E26-E27 -> -0.0030806931 | G28: BIG BAG HE NAC | H28: 112 | I28: 168
B30: TEMPORALES | D30: Capacidad ™ | E30: % | I30: TM
B31: TEMPORAL 1 | C31: 247 | D31: 2142 | E31: =+C31/D31 -> 0.11531279 | G31: CB 25 Kg. | H31: 13420 | I31: 335.5
B32: TEMPORAL 2 | C32: 1248 | D32: 1890 | E32: =+C32/D32 -> 0.66031746 | G32: CB 25 Kg. PINGÜINO | H32: 1086 | I32: 27.15
B33: MISTI | C33: 679 | D33: 3006 | E33: =+C33/D33 -> 0.22588157 | G33: CB BIGBAG x 1.5TM | H33: 165 | I33: 247.5
C34: =+SUM(C31:C33) -> 2174 | D34: =+SUM(D31:D33) -> 7038 | E34: =+C34/D34 -> 0.30889457 | G34: filler | H34: 30 | I34: 45
G35: SUPER FILLER | H35: 131 | I35: 196.5
B36: CARROS | G36: CEM MICROFISURAS | H36: 21 | I36: 31.5
B37: PLAYA | C37: LLAMADO | D37: PROCESO DE C | E37: TOTAL | G37: CARBONATO 1.5 | H37: 36 | I37: =+H37*1.5 -> 54 | J37: 56 BB de calidad
B38: 9 | C38: 1 | D38: 15 | E38: =+SUM(B38:D38) -> 25
E39: RENDIMIENTO
F40: Operativos | G40: Falla
A41: H1 | B41: 0 | C41: 2243 | D41: 2400 | E41: =+C41/D41 -> 0.93458333 | F41: 7
...

Sheet 08.06
B1: 45816 | E1: ME JUNIO
E2: 204590
B3: DESPACHO DEL DÍA POR TIPO DE CEMENTO | H3: PLAN | I3: REAL | J3: %
D4: =D25 -> 3274.306 | F4: LUNES | G4: 45810 | H4: 7474 | I4: 6545.779 | J4: =+I4/H4 -> 0.87580666
B5: CEM. FRONTERA GU X 42.5 KG | C5: 720 | D5: 30.652 | E5: =+D5/$D$4 -> 0.0093613731 | F5: MARTES | G5: 45811 | H5: 8291 | I5: 8122.253 | J5: =+I5/H5 -> 0.97964697
B6: CEMENTO FRONTERA IP x 42.5 KG | C6: 6180 | D6: 263.914 | E6: =+D6/$D$4 -> 0.080601508 | F6: MIÉRCOLES | G6: 45812 | H6: 7668 | I6: 7050.14 | J6: =+I6/H6 -> 0.91942358
B7: CEMENTO HS+R X 42.5 KG RUMI | C7: 4550 | D7: 193.79 | E7: =+D7/$D$4 -> 0.059185061 | F7: JUEVES | G7: 45813 | H7: 8120 | I7: 7708.56 | J7: =+I7/H7 -> 0.94933005
B8: CEMENTO PORTLAND TIPO I X 42.5 KG YURA | C8: 3092 | D8: 131.77 | E8: =+D8/$D$4 -> 0.040243642 | F8: VIERNES | G8: 45814 | H8: 7820 | I8: 6745.45 | J8: =+I8/H8 -> 0.86258951
B9: CEMENTO YURA ANTISALITRE (MS) X 42.5 KG | C9: 10265 | D9: 438.044 | E9: =+D9/$D$4 -> 0.13378224 | F9: SÁBADO | G9: 45815 | H9: 6286 | I9: 6600.55 | J9: =+I9/H9 -> 1.0500398
B10: CEMENTO YURA MAX (HS) X 42.5KG | C10: 19497 | D10: 831.792 | E10: =+D10/$D$4 -> 0.25403612 | F10: DOMINGO | G10: 45816 | H10: 3782 | I10: 3274.306 | J10: =+I10/H10 -> 0.86576044
B11: CEMENTO YURA PRO (HE) 42.5KG | C11: 2375 | D11: 101.434 | E11: =+D11/$D$4 -> 0.030978778 | H11: =+SUM(H4:H10) -> 49441 | I11: =+SUM(I4:I10) -> 46047.038 | J11: =+I11/H11 -> 0.93135329
B12: CEM.PORTL.IP(GRADO CORRIENTE)X25KG CHILE | E12: =+D12/$D$4 -> 0
B13: CEMENTO BLANCO X 25 KG YURA NACIONAL | E13: =+D13/$D$4 -> 0
B14: CEMENTO YURA MAX BBx1.5TM INC.ENV | C14: 40 | D14: 60.1 | E14: =+D14/$D$4 -> 0.018355035
B15: CEMENTO YURA PRO (HE) BBx1.5TM INC.ENV | C15: 215 | D15: 324.15 | E15: =+D15/$D$4 -> 0.098998078
B16: CEM. PORT. PUZ. IP BBx1.5TM INC.ENV YURA | C16: 64 | D16: 96.22 | E16: =+D16/$D$4 -> 0.02938638
B17: CEM ALT REST IN HE BB1.5TM YURA ENV CHIL | C17: 158 | D17: 238.25 | E17: =+D17/$D$4 -> 0.072763511
B18: FILLER INDUSTRIAL BB1.5TM | C18: 68 | D18: 102.46 | E18: =+D18/$D$4 -> 0.031292127
B19: FILLER INDUSTRIAL BB1.5TM | E19: =+D19/$D$4 -> 0 | H19: 2024 | I19: 2025
B20: SUPER SCM BIGBAG X 1.5 TM YURA | E20: =+D20/$D$4 -> 0 | G20: ENERO | H20: 204007.8 | I20: 190629.13 | J20: =+I20/H20 -> 0.93442077
E21: =+D21/$D$4 -> 0 | G21: FEBRERO | H21: 186305.94 | I21: 182874.29 | J21: =+I21/H21 -> 0.98158052
B22: CEMENTO YURA PRO (HE) GRANEL EN BOMBONA | D22: 181.75 | E22: =+D22/$D$4 -> 0.055507946 | G22: MARZO | H22: 199570.19 | I22: 197224.22 | J22: =+I22/H22 -> 0.98824488
B23: CEMENTO YURA MAX GRANEL BOMBONA | D23: 64.64 | E23: =+D23/$D$4 -> 0.019741588 | G23: ABRIL | H23: 205343.73 | I23: 198970.76 | J23: =+I23/H23 -> 0.96896438
B24: CEMENTO YURA IP A GRANEL EN BOMBONA | D24: 215.34 | E24: =+D24/$D$4 -> 0.065766608 | G24: MAYO | H24: 209473.77 | I24: 212393.17 | J24: =+I24/H24 -> 1.0139368
B25: DESPACHO T.M. DEL DIA | D25: =SUM(D5:D24) -> 3274.306 | H25: =+SUM(H20:H24) -> 1004701.4 | I25: =+SUM(I20:I24) -> 982091.56 | J25: =+I25/H25 -> 0.97749593
B26: ACUMULADO MES | D26: 51538.98 | E26: =+D26/E2 -> 0.25191349
D27: =+(E2/30)*8 -> 54557.333 | E27: =+D27/E2 -> 0.26666667 | I27: TM
D28: =+D26-D27 -> -3018.3533 | E28: =+E26-E27 -> -0.014753181 | G28: BIG BAG HE NAC | H28: 112 | I28: 168
B30: TEMPORALES | D30: Capacidad ™ | E30: % | I30: TM
B31: TEMPORAL 1 | C31: 1031 | D31: 2142 | E31: =+C31/D31 -> 0.48132586 | G31: CB 25 Kg. | H31: 12214 | I31: 305.35
B32: TEMPORAL 2 | C32: 1201 | D32: 1890 | E32: =+C32/D32 -> 0.63544974 | G32: CB 25 Kg. PINGÜINO | H32: 1086 | I32: 27.15
B33: MISTI | C33: 2305 | D33: 3006 | E33: =+C33/D33 -> 0.76679973 | G33: CB BIGBAG x 1.5TM | H33: 146 | I33: 219
C34: =+SUM(C31:C33) -> 4537 | D34: =+SUM(D31:D33) -> 7038 | E34: =+C34/D34 -> 0.64464336 | G34: filler | H34: 4 | I34: 6
G35: SUPER FILLER | H35: 116 | I35: 174
B36: CARROS | G36: CEM MICROFISURAS | H36: 23 | I36: 34.5
B37: PLAYA | C37: LLAMADO | D37: PROCESO DE C | E37: TOTAL | G37: CARBONATO 1.5 | H37: 73 | I37: 193.5 | J37: 56 BB de calidad
B38: 5 | C38: 1 | D38: 5 | E38: =+SUM(B38:D38) -> 11
E39: RENDIMIENTO
F40: Operativos | G40: Falla
A41: H1 | B41: 0 | C41: 2243 | D41: 2400 | E41: =+C41/D41 -> 0.93458333 | F41: 7
...

Sheet 09.06
B1: =TODAY()-1 -> 46171 | E1: ME JUNIO
E2: 204590
B3: DESPACHO DEL DÍA POR TIPO DE CEMENTO | H3: PLAN | I3: REAL | J3: %
D4: =D25 -> 6429.381 | F4: LUNES | G4: 45810 | H4: 7565 | I4: 6429.381 | J4: =+I4/H4 -> 0.84988513
B5: CEM. FRONTERA GU X 42.5 KG | C5: 2270 | D5: 96.802 | E5: =+D5/$D$4 -> 0.015056193 | F5: MARTES | G5: 45811 | H5: 8240 | J5: =+I5/H5 -> 0
B6: CEMENTO FRONTERA IP x 42.5 KG | C6: 11265 | D6: 480.462 | E6: =+D6/$D$4 -> 0.074729122 | F6: MIÉRCOLES | G6: 45812 | H6: 7539 | J6: =+I6/H6 -> 0
B7: CEMENTO HS+R X 42.5 KG RUMI | C7: 15473 | D7: 659.784 | E7: =+D7/$D$4 -> 0.10262014 | F7: JUEVES | G7: 45813 | H7: 8593 | J7: =+I7/H7 -> 0
B8: CEMENTO PORTLAND TIPO I X 42.5 KG YURA | C8: 1620 | D8: 68.99 | E8: =+D8/$D$4 -> 0.010730426 | F8: VIERNES | G8: 45814 | H8: 7777 | J8: =+I8/H8 -> 0
B9: CEMENTO YURA ANTISALITRE (MS) X 42.5 KG | C9: 23147 | D9: 987.724 | E9: =+D9/$D$4 -> 0.15362661 | F9: SÁBADO | G9: 45815 | H9: 6874 | J9: =+I9/H9 -> 0
B10: CEMENTO YURA MAX (HS) X 42.5KG | C10: 44963 | D10: 1918.725 | E10: =+D10/$D$4 -> 0.29843075 | F10: DOMINGO | G10: 45816 | H10: 3829 | J10: =+I10/H10 -> 0
B11: CEMENTO YURA PRO (HE) 42.5KG | C11: 9087 | D11: 388.084 | E11: =+D11/$D$4 -> 0.060361021 | H11: =+SUM(H4:H10) -> 50417 | I11: =+SUM(I4:I10) -> 6429.381 | J11: =+I11/H11 -> 0.12752407
B12: CEM.PORTL.IP(GRADO CORRIENTE)X25KG CHILE | E12: =+D12/$D$4 -> 0
B13: CEMENTO BLANCO X 25 KG YURA NACIONAL | E13: =+D13/$D$4 -> 0
B14: CEM ALT REST IN HE BB1.5TM YURA ENV CHIL | C14: 291 | D14: 439.59 | E14: =+D14/$D$4 -> 0.068372056
B15: CEM. PORT. I BBx1.5TM INC.ENV YURA | C15: 66 | D15: 99.5 | E15: =+D15/$D$4 -> 0.015475829
B16: CEM. PORT. PUZ. IP BBx1.5TM INC.ENV YURA | C16: 87 | D16: 130.64 | E16: =+D16/$D$4 -> 0.020319219
B17: CEM.ANTISALITRE HS BBx1.5TM INC.ENV YURA | C17: 20 | D17: 30.22 | E17: =+D17/$D$4 -> 0.004700297
B18: CEMENTO YURA MAX BBx1.5TM INC.ENV | C18: 127 | D18: 190.85 | E18: =+D18/$D$4 -> 0.02968404
B19: CEMENTO YURA PRO (HE) BBx1.5TM INC.ENV | C19: 261 | D19: 394.58 | E19: =+D19/$D$4 -> 0.061371382 | H19: 2024 | I19: 2025
B20: CEMENTO BLANCO A GRANEL EN BBx1.5 YURA | C20: 20 | D20: 30.01 | E20: =+D20/$D$4 -> 0.0046676344 | G20: ENERO | H20: 204007.8 | I20: 190629.13 | J20: =+I20/H20 -> 0.93442077
E21: =+D21/$D$4 -> 0 | G21: FEBRERO | H21: 186305.94 | I21: 182874.29 | J21: =+I21/H21 -> 0.98158052
B22: CEMENTO YURA IP A GRANEL EN BOMBONA | D22: 124.24 | E22: =+D22/$D$4 -> 0.019323789 | G22: MARZO | H22: 199570.19 | I22: 197224.22 | J22: =+I22/H22 -> 0.98824488
B23: CEMENTO YURA MAX GRANEL BOMBONA | D23: 88.97 | E23: =+D23/$D$4 -> 0.013838035 | G23: ABRIL | H23: 205343.73 | I23: 198970.76 | J23: =+I23/H23 -> 0.96896438
B24: CEMENTO YURA PRO (HE) GRANEL EN BOMBONA | D24: 300.21 | E24: =+D24/$D$4 -> 0.046693453 | G24: MAYO | H24: 209473.77 | I24: 212393.17 | J24: =+I24/H24 -> 1.0139368
B25: DESPACHO T.M. DEL DIA | D25: =SUM(D5:D24) -> 6429.381 | H25: =+SUM(H20:H24) -> 1004701.4 | I25: =+SUM(I20:I24) -> 982091.56 | J25: =+I25/H25 -> 0.97749593
B26: ACUMULADO MES | D26: 57968.361 | E26: =+D26/E2 -> 0.28333917 | I26: =+H25-I25 -> 22609.876
D27: =+(E2/30)*9 -> 61377 | E27: =+D27/E2 -> 0.3
D28: =+D26-D27 -> -3408.639 | E28: =+E26-E27 -> -0.016660829
B30: TEMPORALES | D30: Capacidad ™ | E30: % | I30: TM
B31: TEMPORAL 1 | C31: 488 | D31: 2142 | E31: =+C31/D31 -> 0.22782446 | G31: CB 25 Kg. | H31: 12214 | I31: 305.35
B32: TEMPORAL 2 | C32: 1083 | D32: 1890 | E32: =+C32/D32 -> 0.57301587 | G32: CB 25 Kg. PINGÜINO | H32: 1086 | I32: 27.15
B33: MISTI | C33: 1529 | D33: 3006 | E33: =+C33/D33 -> 0.50864937 | G33: CB BIGBAG x 1.5TM | H33: 126 | I33: 189
C34: =+SUM(C31:C33) -> 3100 | D34: =+SUM(D31:D33) -> 7038 | E34: =+C34/D34 -> 0.44046604 | G34: filler | H34: 4 | I34: 6
G35: SUPER FILLER | H35: 116 | I35: 174
B36: CARROS | G36: CEM MICROFISURAS | H36: 23 | I36: 34.5
B37: PLAYA | C37: LLAMADO | D37: PROCESO DE C | E37: TOTAL | G37: CARBONATO 1.5 | H37: 73 | I37: 193.5 | J37: 56 BB de calidad
B38: 17 | C38: 9 | D38: 26 | E38: =+SUM(B38:D38) -> 52
E39: RENDIMIENTO
F40: Operativos | G40: Falla
A41: H1 | B41: 0 | C41: 2243 | D41: 2400 | E41: =+C41/D41 -> 0.93458333 | F41: 7
...

Sheet 10.06
B1: 45818 | E1: ME JUNIO
E2: 204590
B3: DESPACHO DEL DÍA POR TIPO DE CEMENTO | H3: PLAN | I3: REAL | J3: %
D4: =D25 -> 8958.08 | F4: LUNES | G4: 45810 | H4: 7565 | I4: 6429.381 | J4: =+I4/H4 -> 0.84988513
B5: CEM. FRONTERA GU X 42.5 KG | C5: 7180 | D5: 306.242 | E5: =+D5/$D$4 -> 0.03418612 | F5: MARTES | G5: 45811 | H5: 8240 | I5: 8958.08 | J5: =+I5/H5 -> 1.0871456
B6: CEMENTO FRONTERA IP x 42.5 KG | C6: 17874 | D6: 762.746 | E6: =+D6/$D$4 -> 0.085146147 | F6: MIÉRCOLES | G6: 45812 | H6: 7539 | J6: =+I6/H6 -> 0
B7: CEMENTO HS+R X 42.5 KG RUMI | C7: 23885 | D7: 1019.254 | E7: =+D7/$D$4 -> 0.11378041 | F7: JUEVES | G7: 45813 | H7: 8593 | J7: =+I7/H7 -> 0
B8: CEMENTO PORTLAND TIPO I X 42.5 KG YURA | C8: 4195 | D8: 178.91 | E8: =+D8/$D$4 -> 0.019971914 | F8: VIERNES | G8: 45814 | H8: 7777 | J8: =+I8/H8 -> 0
B9: CEMENTO YURA ANTISALITRE (MS) X 42.5 KG | C9: 32200 | D9: 1372.578 | E9: =+D9/$D$4 -> 0.15322234 | F9: SÁBADO | G9: 45815 | H9: 6874 | J9: =+I9/H9 -> 0
B10: CEMENTO YURA MAX (HS) X 42.5KG | C10: 56385 | D10: 2405.642 | E10: =+D10/$D$4 -> 0.26854438 | F10: DOMINGO | G10: 45816 | H10: 3829 | J10: =+I10/H10 -> 0
B11: CEMENTO YURA PRO (HE) 42.5KG | C11: 12315 | D11: 524.878 | E11: =+D11/$D$4 -> 0.05859269 | H11: =+SUM(H4:H5) -> 15805 | I11: =+SUM(I4:I10) -> 15387.461 | J11: =+I11/H11 -> 0.97358184
B12: CEM.PORTL.IP(GRADO CORRIENTE)X25KG CHILE | E12: =+D12/$D$4 -> 0
B13: CEMENTO BLANCO X 25 KG YURA NACIONAL | E13: =+D13/$D$4 -> 0
B14: CEM ALT REST IN HE BB1.5TM YURA ENV CHIL | C14: 464 | D14: 701.1 | E14: =+D14/$D$4 -> 0.078264539
B15: CEM. PORT. I BBx1.5TM INC.ENV YURA | C15: 20 | D15: 30.21 | E15: =+D15/$D$4 -> 0.0033723744
B16: CEM. PORT. PUZ. IP BBx1.5TM INC.ENV YURA | C16: 23 | D16: 34.57 | E16: =+D16/$D$4 -> 0.0038590859
B17: CEM.YURA ANTISALITRE MS BBx1.5TM INC.ENV | C17: 46 | D17: 69.16 | E17: =+D17/$D$4 -> 0.0077204044
B18: CEMENTO YURA MAX BBx1.5TM INC.ENV | C18: 185 | D18: 278.43 | E18: =+D18/$D$4 -> 0.031081437
B19: CEMENTO YURA PRO (HE) BBx1.5TM INC.ENV | C19: 302 | D19: 455.75 | E19: =+D19/$D$4 -> 0.050875857 | H19: 2024 | I19: 2025
B20: CEMENTO BLANCO A GRANEL EN BBx1.5 YURA | E20: =+D20/$D$4 -> 0 | G20: ENERO | H20: 204007.8 | I20: 190629.13 | J20: =+I20/H20 -> 0.93442077
E21: =+D21/$D$4 -> 0 | G21: FEBRERO | H21: 186305.94 | I21: 182874.29 | J21: =+I21/H21 -> 0.98158052
B22: CEMENTO YURA IP A GRANEL EN BOMBONA | D22: 183.21 | E22: =+D22/$D$4 -> 0.020451927 | G22: MARZO | H22: 199570.19 | I22: 197224.22 | J22: =+I22/H22 -> 0.98824488
B23: CEMENTO YURA MAX GRANEL BOMBONA | D23: 29.75 | E23: =+D23/$D$4 -> 0.0033210241 | G23: ABRIL | H23: 205343.73 | I23: 198970.76 | J23: =+I23/H23 -> 0.96896438
B24: CEMENTO YURA PRO (HE) GRANEL EN BOMBONA | D24: 605.65 | E24: =+D24/$D$4 -> 0.067609354 | G24: MAYO | H24: 209473.77 | I24: 212393.17 | J24: =+I24/H24 -> 1.0139368
B25: DESPACHO T.M. DEL DIA | D25: =SUM(D5:D24) -> 8958.08 | H25: =+SUM(H20:H24) -> 1004701.4 | I25: =+SUM(I20:I24) -> 982091.56 | J25: =+I25/H25 -> 0.97749593
B26: ACUMULADO MES | D26: 66958.251 | E26: =+D26/E2 -> 0.32728017 | I26: =+I25-H25 -> -22609.876
D27: =+(E2/30)*10 -> 68196.667 | E27: =+D27/E2 -> 0.33333333
D28: =+D26-D27 -> -1238.4157 | E28: =+E26-E27 -> -0.0060531583
B30: TEMPORALES | D30: Capacidad ™ | E30: % | I30: TM
B31: TEMPORAL 1 | C31: 589 | D31: 2142 | E31: =+C31/D31 -> 0.27497666 | G31: CB 25 Kg. | H31: 12214 | I31: 305.35
B32: TEMPORAL 2 | C32: 1116 | D32: 1890 | E32: =+C32/D32 -> 0.59047619 | G32: CB 25 Kg. PINGÜINO | H32: 1086 | I32: 27.15
B33: MISTI | C33: 644 | D33: 3006 | E33: =+C33/D33 -> 0.21423819 | G33: CB BIGBAG x 1.5TM | H33: 126 | I33: 189
C34: =+SUM(C31:C33) -> 2349 | D34: =+SUM(D31:D33) -> 7038 | E34: =+C34/D34 -> 0.33375959 | G34: filler | H34: 4 | I34: 6
G35: SUPER FILLER | H35: 116 | I35: 174
B36: CARROS | G36: CEM MICROFISURAS | H36: 23 | I36: 34.5
B37: PLAYA | C37: LLAMADO | D37: PROCESO DE C | E37: TOTAL | G37: CARBONATO 1.5 | H37: 73 | I37: 193.5 | J37: 56 BB de calidad
B38: 34 | C38: 7 | D38: 16 | E38: =+SUM(B38:D38) -> 57
E39: RENDIMIENTO
F40: Operativos | G40: Falla
A41: H1 | B41: 0 | C41: 2243 | D41: 2400 | E41: =+C41/D41 -> 0.93458333 | F41: 7
...

Sheet 11.06
B1: 45819 | E1: ME JUNIO
E2: 204590
B3: DESPACHO DEL DÍA POR TIPO DE CEMENTO | H3: PLAN | I3: REAL | J3: %
D4: =D21 -> 8950.208 | F4: LUNES | G4: 45810 | H4: 7565 | I4: 6429.381 | J4: =+I4/H4 -> 0.84988513
B5: CEM. FRONTERA GU X 42.5 KG | C5: 4639 | D5: 198.018 | E5: =+D5/$D$4 -> 0.022124402 | F5: MARTES | G5: 45811 | H5: 8240 | I5: 8958.08 | J5: =+I5/H5 -> 1.0871456
B6: CEMENTO FRONTERA IP x 42.5 KG | C6: 15810 | D6: 674.565 | E6: =+D6/$D$4 -> 0.075368639 | F6: MIÉRCOLES | G6: 45812 | H6: 7539 | I6: 8950.208 | J6: =+I6/H6 -> 1.1871877
B7: CEMENTO HS+R X 42.5 KG RUMI | C7: 20774 | D7: 885.261 | E7: =+D7/$D$4 -> 0.098909545 | F7: JUEVES | G7: 45813 | H7: 8593 | J7: =+I7/H7 -> 0
B8: CEMENTO PORTLAND TIPO I X 42.5 KG YURA | C8: 5335 | D8: 227.36 | E8: =+D8/$D$4 -> 0.025402762 | F8: VIERNES | G8: 45814 | H8: 7777 | J8: =+I8/H8 -> 0
B9: CEMENTO YURA ANTISALITRE (MS) X 42.5 KG | C9: 40899 | D9: 1743.902 | E9: =+D9/$D$4 -> 0.19484486 | F9: SÁBADO | G9: 45815 | H9: 6874 | J9: =+I9/H9 -> 0
B10: CEMENTO YURA MAX (HS) X 42.5KG | C10: 51511 | D10: 2196.702 | E10: =+D10/$D$4 -> 0.24543586 | F10: DOMINGO | G10: 45816 | H10: 3829 | J10: =+I10/H10 -> 0
B11: CEMENTO YURA PRO (HE) 42.5KG | C11: 13140 | D11: 560.588 | E11: =+D11/$D$4 -> 0.062634075 | H11: =+SUM(H4:H6) -> 23344 | I11: =+SUM(I4:I10) -> 24337.669 | J11: =+I11/H11 -> 1.0425664
B12: CEM. PORT. I BBx1.5TM INC.ENV YURA | C12: 40 | D12: 60.24 | E12: =+D12/$D$4 -> 0.0067305698
B13: CEMENTO YURA PRO (HE) BBx1.5TM INC.ENV | C13: 343 | D13: 518.288 | E13: =+D13/$D$4 -> 0.057907928 | H13: 2024 | I13: 2025
B14: CEM ALT REST IN HE BB1.5TM YURA ENV CHIL | C14: 366 | D14: 552.34 | E14: =+D14/$D$4 -> 0.061712532 | G14: ENERO | H14: 204007.8 | I14: 190629.13 | J14: =+I14/H14 -> 0.93442077
B15: CEM. PORT. PUZ. IP BBx1.5TM INC.ENV YURA | C15: 82 | D15: 123.31 | E15: =+D15/$D$4 -> 0.013777333 | G15: FEBRERO | H15: 186305.94 | I15: 182874.29 | J15: =+I15/H15 -> 0.98158052
B16: CEMENTO YURA MAX BBx1.5TM INC.ENV | C16: 262 | D16: 394.094 | E16: =+D16/$D$4 -> 0.044031826 | G16: MARZO | H16: 199570.19 | I16: 197224.22 | J16: =+I16/H16 -> 0.98824488
B17: CEMENTO YURA PRO (HE) GRANEL EN BOMBONA | D17: 479.74 | E17: =+D17/$D$4 -> 0.053600989 | G17: ABRIL | H17: 205343.73 | I17: 198970.76 | J17: =+I17/H17 -> 0.96896438
B18: CEMENTO YURA IP A GRANEL EN BOMBONA | D18: 246.46 | E18: =+D18/$D$4 -> 0.02753679 | G18: MAYO | H18: 209473.77 | I18: 212393.17 | J18: =+I18/H18 -> 1.0139368
